<?xml version="1.0" ?>
<robot name="mvp_arm_6dof" xmlns:xacro="http://www.ros.org/wiki/xacro">

<xacro:include filename="$(find mvp_arm_6dof_description)/urdf/materials.xacro" />
<xacro:include filename="$(find mvp_arm_6dof_description)/urdf/mvp_arm_6dof.trans" />
<xacro:include filename="$(find mvp_arm_6dof_description)/urdf/mvp_arm_6dof.gazebo" />
<link name="base_link">
  <inertial>
    <origin rpy="0 0 0" xyz="1.5273427923512274e-08 -0.0012615194115251204 0.015200351763726439"/>
    <mass value="1.6606259711147333"/>
    <inertia ixx="0.006748" ixy="0.0" ixz="-0.0" iyy="0.007016" iyz="4.2e-05" izz="0.012699"/>
  </inertial>
  <visual>
    <origin rpy="0 0 0" xyz="0 0 0"/>
    <geometry>
      <mesh filename="package://mvp_arm_6dof_description/meshes/base_link.stl" scale="0.001 0.001 0.001"/>
    </geometry>
    <material name="silver"/>
  </visual>
  <collision>
    <origin rpy="0 0 0" xyz="0 0 0"/>
    <geometry>
      <mesh filename="package://mvp_arm_6dof_description/meshes/base_link.stl" scale="0.001 0.001 0.001"/>
    </geometry>
  </collision>
</link>

<link name="f3Bracket_1">
  <inertial>
    <origin rpy="0 0 0" xyz="0.0018413874270871398 8.06819888676813e-15 2.0816681711721685e-17"/>
    <mass value="0.0016262220015435807"/>
    <inertia ixx="0.0" ixy="-0.0" ixz="-0.0" iyy="0.0" iyz="0.0" izz="0.0"/>
  </inertial>
  <visual>
    <origin rpy="0 0 0" xyz="0.019 0.01475 -0.041"/>
    <geometry>
      <mesh filename="package://mvp_arm_6dof_description/meshes/f3Bracket_1.stl" scale="0.001 0.001 0.001"/>
    </geometry>
    <material name="silver"/>
  </visual>
  <collision>
    <origin rpy="0 0 0" xyz="0.019 0.01475 -0.041"/>
    <geometry>
      <mesh filename="package://mvp_arm_6dof_description/meshes/f3Bracket_1.stl" scale="0.001 0.001 0.001"/>
    </geometry>
  </collision>
</link>

<link name="f3Bracket__1__1">
  <inertial>
    <origin rpy="0 0 0" xyz="-0.0018413874270886074 6.831341048396666e-15 -3.469446951953614e-17"/>
    <mass value="0.0016262220015435807"/>
    <inertia ixx="0.0" ixy="0.0" ixz="0.0" iyy="0.0" iyz="-0.0" izz="0.0"/>
  </inertial>
  <visual>
    <origin rpy="0 0 0" xyz="-0.019 0.01475 -0.041"/>
    <geometry>
      <mesh filename="package://mvp_arm_6dof_description/meshes/f3Bracket__1__1.stl" scale="0.001 0.001 0.001"/>
    </geometry>
    <material name="silver"/>
  </visual>
  <collision>
    <origin rpy="0 0 0" xyz="-0.019 0.01475 -0.041"/>
    <geometry>
      <mesh filename="package://mvp_arm_6dof_description/meshes/f3Bracket__1__1.stl" scale="0.001 0.001 0.001"/>
    </geometry>
  </collision>
</link>

<link name="AX12A_servo_1">
  <inertial>
    <origin rpy="0 0 0" xyz="0.01350070935914761 -0.005876867522658821 -0.01479497142329602"/>
    <mass value="0.3366787209762054"/>
    <inertia ixx="9.7e-05" ixy="-0.0" ixz="-0.0" iyy="5.4e-05" iyz="-1e-06" izz="8.2e-05"/>
  </inertial>
  <visual>
    <origin rpy="0 0 0" xyz="0.0135 0.00675 -0.057"/>
    <geometry>
      <mesh filename="package://mvp_arm_6dof_description/meshes/AX12A_servo_1.stl" scale="0.001 0.001 0.001"/>
    </geometry>
    <material name="silver"/>
  </visual>
  <collision>
    <origin rpy="0 0 0" xyz="0.0135 0.00675 -0.057"/>
    <geometry>
      <mesh filename="package://mvp_arm_6dof_description/meshes/AX12A_servo_1.stl" scale="0.001 0.001 0.001"/>
    </geometry>
  </collision>
</link>

<link name="lid_1">
  <inertial>
    <origin rpy="0 0 0" xyz="-1.0658141036401502e-15 2.4713564528155986e-15 0.0024995000000005013"/>
    <mass value="0.7384184020105663"/>
    <inertia ixx="0.001114" ixy="0.0" ixz="0.0" iyy="0.001114" iyz="-0.0" izz="0.002224"/>
  </inertial>
  <visual>
    <origin rpy="0 0 0" xyz="0.0 -0.0 -0.06175"/>
    <geometry>
      <mesh filename="package://mvp_arm_6dof_description/meshes/lid_1.stl" scale="0.001 0.001 0.001"/>
    </geometry>
    <material name="silver"/>
  </visual>
  <collision>
    <origin rpy="0 0 0" xyz="0.0 -0.0 -0.06175"/>
    <geometry>
      <mesh filename="package://mvp_arm_6dof_description/meshes/lid_1.stl" scale="0.001 0.001 0.001"/>
    </geometry>
  </collision>
</link>

<link name="f3Bracket__2__1">
  <inertial>
    <origin rpy="0 0 0" xyz="-4.2188474935755947e-16 8.477663016037695e-15 0.0018408874270881004"/>
    <mass value="0.0016262220015435807"/>
    <inertia ixx="0.0" ixy="0.0" ixz="0.0" iyy="0.0" iyz="-0.0" izz="0.0"/>
  </inertial>
  <visual>
    <origin rpy="0 0 0" xyz="0.0 -0.0 -0.06675"/>
    <geometry>
      <mesh filename="package://mvp_arm_6dof_description/meshes/f3Bracket__2__1.stl" scale="0.001 0.001 0.001"/>
    </geometry>
    <material name="silver"/>
  </visual>
  <collision>
    <origin rpy="0 0 0" xyz="0.0 -0.0 -0.06675"/>
    <geometry>
      <mesh filename="package://mvp_arm_6dof_description/meshes/f3Bracket__2__1.stl" scale="0.001 0.001 0.001"/>
    </geometry>
  </collision>
</link>

<link name="AX12A_servo__1__1">
  <inertial>
    <origin rpy="0 0 0" xyz="0.014794971423295564 0.007999290640854232 0.02337263247733931"/>
    <mass value="0.3366787209762054"/>
    <inertia ixx="8.2e-05" ixy="-0.0" ixz="1e-06" iyy="9.7e-05" iyz="0.0" izz="5.4e-05"/>
  </inertial>
  <visual>
    <origin rpy="0 0 0" xyz="0.016 0.008 -0.07225"/>
    <geometry>
      <mesh filename="package://mvp_arm_6dof_description/meshes/AX12A_servo__1__1.stl" scale="0.001 0.001 0.001"/>
    </geometry>
    <material name="silver"/>
  </visual>
  <collision>
    <origin rpy="0 0 0" xyz="0.016 0.008 -0.07225"/>
    <geometry>
      <mesh filename="package://mvp_arm_6dof_description/meshes/AX12A_servo__1__1.stl" scale="0.001 0.001 0.001"/>
    </geometry>
  </collision>
</link>

<link name="f2Bracket_1">
  <inertial>
    <origin rpy="0 0 0" xyz="0.02099999999999843 0.011463049476928342 0.011458018229762487"/>
    <mass value="0.0037556666472927302"/>
    <inertia ixx="1e-06" ixy="0.0" ixz="-0.0" iyy="2e-06" iyz="-0.0" izz="2e-06"/>
  </inertial>
  <visual>
    <origin rpy="0 0 0" xyz="0.02075 -0.0 -0.10825"/>
    <geometry>
      <mesh filename="package://mvp_arm_6dof_description/meshes/f2Bracket_1.stl" scale="0.001 0.001 0.001"/>
    </geometry>
    <material name="silver"/>
  </visual>
  <collision>
    <origin rpy="0 0 0" xyz="0.02075 -0.0 -0.10825"/>
    <geometry>
      <mesh filename="package://mvp_arm_6dof_description/meshes/f2Bracket_1.stl" scale="0.001 0.001 0.001"/>
    </geometry>
  </collision>
</link>

<link name="shoulderArm__1">
  <inertial>
    <origin rpy="0 0 0" xyz="1.7088652541630278e-15 0.05303289486060747 0.05303290188896653"/>
    <mass value="1.4306625"/>
    <inertia ixx="0.002769" ixy="-0.0" ixz="-0.0" iyy="0.001626" iyz="-0.001298" izz="0.001626"/>
  </inertial>
  <visual>
    <origin rpy="0 0 0" xyz="-0.00025 -0.018709 -0.126952"/>
    <geometry>
      <mesh filename="package://mvp_arm_6dof_description/meshes/shoulderArm__1.stl" scale="0.001 0.001 0.001"/>
    </geometry>
    <material name="silver"/>
  </visual>
  <collision>
    <origin rpy="0 0 0" xyz="-0.00025 -0.018709 -0.126952"/>
    <geometry>
      <mesh filename="package://mvp_arm_6dof_description/meshes/shoulderArm__1.stl" scale="0.001 0.001 0.001"/>
    </geometry>
  </collision>
</link>

<link name="f3Bracket__3__1">
  <inertial>
    <origin rpy="0 0 0" xyz="5.250465860695552e-15 0.0013019609860796533 0.0013019680144470969"/>
    <mass value="0.0016262220015435807"/>
    <inertia ixx="0.0" ixy="-0.0" ixz="0.0" iyy="0.0" iyz="0.0" izz="0.0"/>
  </inertial>
  <visual>
    <origin rpy="0 0 0" xyz="-0.00025 -0.124775 -0.233018"/>
    <geometry>
      <mesh filename="package://mvp_arm_6dof_description/meshes/f3Bracket__3__1.stl" scale="0.001 0.001 0.001"/>
    </geometry>
    <material name="silver"/>
  </visual>
  <collision>
    <origin rpy="0 0 0" xyz="-0.00025 -0.124775 -0.233018"/>
    <geometry>
      <mesh filename="package://mvp_arm_6dof_description/meshes/f3Bracket__3__1.stl" scale="0.001 0.001 0.001"/>
    </geometry>
  </collision>
</link>

<link name="AX12A_servo__2__1">
  <inertial>
    <origin rpy="0 0 0" xyz="0.01479397142330254 0.010869789625758658 0.02218479983944499"/>
    <mass value="0.3366787209762054"/>
    <inertia ixx="8.2e-05" ixy="1e-06" ixz="1e-06" iyy="7.6e-05" iyz="-2.2e-05" izz="7.6e-05"/>
  </inertial>
  <visual>
    <origin rpy="0 0 0" xyz="0.015749 -0.134321 -0.23125"/>
    <geometry>
      <mesh filename="package://mvp_arm_6dof_description/meshes/AX12A_servo__2__1.stl" scale="0.001 0.001 0.001"/>
    </geometry>
    <material name="silver"/>
  </visual>
  <collision>
    <origin rpy="0 0 0" xyz="0.015749 -0.134321 -0.23125"/>
    <geometry>
      <mesh filename="package://mvp_arm_6dof_description/meshes/AX12A_servo__2__1.stl" scale="0.001 0.001 0.001"/>
    </geometry>
  </collision>
</link>

<link name="f2Bracket__1__1">
  <inertial>
    <origin rpy="0 0 0" xyz="0.02099900000000768 -0.011458683360921401 0.011462891374124484"/>
    <mass value="0.0037556666472927302"/>
    <inertia ixx="1e-06" ixy="0.0" ixz="0.0" iyy="2e-06" iyz="0.0" izz="2e-06"/>
  </inertial>
  <visual>
    <origin rpy="0 0 0" xyz="0.020499 -0.15412 -0.262363"/>
    <geometry>
      <mesh filename="package://mvp_arm_6dof_description/meshes/f2Bracket__1__1.stl" scale="0.001 0.001 0.001"/>
    </geometry>
    <material name="silver"/>
  </visual>
  <collision>
    <origin rpy="0 0 0" xyz="0.020499 -0.15412 -0.262363"/>
    <geometry>
      <mesh filename="package://mvp_arm_6dof_description/meshes/f2Bracket__1__1.stl" scale="0.001 0.001 0.001"/>
    </geometry>
  </collision>
</link>

<link name="axis3-4_connector__1">
  <inertial>
    <origin rpy="0 0 0" xyz="7.741767021180422e-09 -0.013131073230303991 0.013131242967982293"/>
    <mass value="0.2107220147290529"/>
    <inertia ixx="0.000131" ixy="-0.0" ixz="0.0" iyy="9.2e-05" iyz="-1.3e-05" izz="9.2e-05"/>
  </inertial>
  <visual>
    <origin rpy="0 0 0" xyz="-0.0005 -0.135417 -0.281072"/>
    <geometry>
      <mesh filename="package://mvp_arm_6dof_description/meshes/axis3-4_connector__1.stl" scale="0.001 0.001 0.001"/>
    </geometry>
    <material name="silver"/>
  </visual>
  <collision>
    <origin rpy="0 0 0" xyz="-0.0005 -0.135417 -0.281072"/>
    <geometry>
      <mesh filename="package://mvp_arm_6dof_description/meshes/axis3-4_connector__1.stl" scale="0.001 0.001 0.001"/>
    </geometry>
  </collision>
</link>

<link name="f3Bracket__4__1">
  <inertial>
    <origin rpy="0 0 0" xyz="8.331551594464859e-15 0.006959286311871121 -0.00435505918631085"/>
    <mass value="0.0016262220015435807"/>
    <inertia ixx="0.0" ixy="0.0" ixz="-0.0" iyy="0.0" iyz="0.0" izz="0.0"/>
  </inertial>
  <visual>
    <origin rpy="0 0 0" xyz="-0.0005 -0.09193 -0.297689"/>
    <geometry>
      <mesh filename="package://mvp_arm_6dof_description/meshes/f3Bracket__4__1.stl" scale="0.001 0.001 0.001"/>
    </geometry>
    <material name="silver"/>
  </visual>
  <collision>
    <origin rpy="0 0 0" xyz="-0.0005 -0.09193 -0.297689"/>
    <geometry>
      <mesh filename="package://mvp_arm_6dof_description/meshes/f3Bracket__4__1.stl" scale="0.001 0.001 0.001"/>
    </geometry>
  </collision>
</link>

<link name="f3Bracket__5__1">
  <inertial>
    <origin rpy="0 0 0" xyz="1.960920575222458e-14 0.004355228923988971 -0.006959116574192292"/>
    <mass value="0.0016262220015435807"/>
    <inertia ixx="0.0" ixy="0.0" ixz="-0.0" iyy="0.0" iyz="0.0" izz="0.0"/>
  </inertial>
  <visual>
    <origin rpy="0 0 0" xyz="-0.0005 -0.1188 -0.324559"/>
    <geometry>
      <mesh filename="package://mvp_arm_6dof_description/meshes/f3Bracket__5__1.stl" scale="0.001 0.001 0.001"/>
    </geometry>
    <material name="silver"/>
  </visual>
  <collision>
    <origin rpy="0 0 0" xyz="-0.0005 -0.1188 -0.324559"/>
    <geometry>
      <mesh filename="package://mvp_arm_6dof_description/meshes/f3Bracket__5__1.stl" scale="0.001 0.001 0.001"/>
    </geometry>
  </collision>
</link>

<link name="AX12A_servo__3__1">
  <inertial>
    <origin rpy="0 0 0" xyz="-0.005876867522646675 0.0009146721471553626 -0.020007505594804464"/>
    <mass value="0.3366787209762054"/>
    <inertia ixx="5.4e-05" ixy="1e-06" ixz="-1e-06" iyy="9e-05" iyz="8e-06" izz="9e-05"/>
  </inertial>
  <visual>
    <origin rpy="0 0 0" xyz="-0.0085 -0.109255 -0.326326"/>
    <geometry>
      <mesh filename="package://mvp_arm_6dof_description/meshes/AX12A_servo__3__1.stl" scale="0.001 0.001 0.001"/>
    </geometry>
    <material name="silver"/>
  </visual>
  <collision>
    <origin rpy="0 0 0" xyz="-0.0085 -0.109255 -0.326326"/>
    <geometry>
      <mesh filename="package://mvp_arm_6dof_description/meshes/AX12A_servo__3__1.stl" scale="0.001 0.001 0.001"/>
    </geometry>
  </collision>
</link>

<link name="f3Bracket__6__1">
  <inertial>
    <origin rpy="0 0 0" xyz="1.7957857423311907e-14 -0.001301912074779893 0.0013020818124673261"/>
    <mass value="0.0016262220015435807"/>
    <inertia ixx="0.0" ixy="-0.0" ixz="0.0" iyy="0.0" iyz="-0.0" izz="0.0"/>
  </inertial>
  <visual>
    <origin rpy="0 0 0" xyz="-0.01525 -0.09635 -0.320139"/>
    <geometry>
      <mesh filename="package://mvp_arm_6dof_description/meshes/f3Bracket__6__1.stl" scale="0.001 0.001 0.001"/>
    </geometry>
    <material name="silver"/>
  </visual>
  <collision>
    <origin rpy="0 0 0" xyz="-0.01525 -0.09635 -0.320139"/>
    <geometry>
      <mesh filename="package://mvp_arm_6dof_description/meshes/f3Bracket__6__1.stl" scale="0.001 0.001 0.001"/>
    </geometry>
  </collision>
</link>

<link name="axis4ARM__1">
  <inertial>
    <origin rpy="0 0 0" xyz="2.929601006229632e-14 -0.053032748695814015 0.05303291843349328"/>
    <mass value="0.9125625000000004"/>
    <inertia ixx="0.001759" ixy="0.0" ixz="-0.0" iyy="0.000952" iyz="0.000832" izz="0.000952"/>
  </inertial>
  <visual>
    <origin rpy="0 0 0" xyz="-0.01525 -0.095227 -0.321262"/>
    <geometry>
      <mesh filename="package://mvp_arm_6dof_description/meshes/axis4ARM__1.stl" scale="0.001 0.001 0.001"/>
    </geometry>
    <material name="silver"/>
  </visual>
  <collision>
    <origin rpy="0 0 0" xyz="-0.01525 -0.095227 -0.321262"/>
    <geometry>
      <mesh filename="package://mvp_arm_6dof_description/meshes/axis4ARM__1.stl" scale="0.001 0.001 0.001"/>
    </geometry>
  </collision>
</link>

<link name="f3Bracket__7__1">
  <inertial>
    <origin rpy="0 0 0" xyz="4.110253803979447e-14 -0.0013018148212854495 0.001301984558973679"/>
    <mass value="0.0016262220015435807"/>
    <inertia ixx="0.0" ixy="-0.0" ixz="0.0" iyy="0.0" iyz="-0.0" izz="0.0"/>
  </inertial>
  <visual>
    <origin rpy="0 0 0" xyz="-0.01525 0.010839 -0.427328"/>
    <geometry>
      <mesh filename="package://mvp_arm_6dof_description/meshes/f3Bracket__7__1.stl" scale="0.001 0.001 0.001"/>
    </geometry>
    <material name="silver"/>
  </visual>
  <collision>
    <origin rpy="0 0 0" xyz="-0.01525 0.010839 -0.427328"/>
    <geometry>
      <mesh filename="package://mvp_arm_6dof_description/meshes/f3Bracket__7__1.stl" scale="0.001 0.001 0.001"/>
    </geometry>
  </collision>
</link>

<link name="AX12A_servo__4__1">
  <inertial>
    <origin rpy="0 0 0" xyz="0.014793971423341353 -0.010870646646293183 0.022183813198644264"/>
    <mass value="0.3366787209762054"/>
    <inertia ixx="8.2e-05" ixy="-1e-06" ixz="1e-06" iyy="7.6e-05" iyz="2.2e-05" izz="7.6e-05"/>
  </inertial>
  <visual>
    <origin rpy="0 0 0" xyz="0.000749 0.020385 -0.42556"/>
    <geometry>
      <mesh filename="package://mvp_arm_6dof_description/meshes/AX12A_servo__4__1.stl" scale="0.001 0.001 0.001"/>
    </geometry>
    <material name="silver"/>
  </visual>
  <collision>
    <origin rpy="0 0 0" xyz="0.000749 0.020385 -0.42556"/>
    <geometry>
      <mesh filename="package://mvp_arm_6dof_description/meshes/AX12A_servo__4__1.stl" scale="0.001 0.001 0.001"/>
    </geometry>
  </collision>
</link>

<link name="f2Bracket__2__1">
  <inertial>
    <origin rpy="0 0 0" xyz="0.020999000000046463 -0.011462738180973452 -0.011458659788035952"/>
    <mass value="0.0037556666472927302"/>
    <inertia ixx="1e-06" ixy="-0.0" ixz="0.0" iyy="2e-06" iyz="-0.0" izz="2e-06"/>
  </inertial>
  <visual>
    <origin rpy="0 0 0" xyz="0.005499 0.040184 -0.456673"/>
    <geometry>
      <mesh filename="package://mvp_arm_6dof_description/meshes/f2Bracket__2__1.stl" scale="0.001 0.001 0.001"/>
    </geometry>
    <material name="silver"/>
  </visual>
  <collision>
    <origin rpy="0 0 0" xyz="0.005499 0.040184 -0.456673"/>
    <geometry>
      <mesh filename="package://mvp_arm_6dof_description/meshes/f2Bracket__2__1.stl" scale="0.001 0.001 0.001"/>
    </geometry>
  </collision>
</link>

<link name="axis5-6_connector__1">
  <inertial>
    <origin rpy="0 0 0" xyz="-2.2518098496959738e-13 -0.013131095249087704 -0.01313104418317057"/>
    <mass value="0.2107220147290529"/>
    <inertia ixx="8e-05" ixy="-0.0" ixz="0.0" iyy="0.000118" iyz="-1.3e-05" izz="0.000118"/>
  </inertial>
  <visual>
    <origin rpy="0 0 0" xyz="-0.0155 0.058893 -0.43797"/>
    <geometry>
      <mesh filename="package://mvp_arm_6dof_description/meshes/axis5-6_connector__1.stl" scale="0.001 0.001 0.001"/>
    </geometry>
    <material name="silver"/>
  </visual>
  <collision>
    <origin rpy="0 0 0" xyz="-0.0155 0.058893 -0.43797"/>
    <geometry>
      <mesh filename="package://mvp_arm_6dof_description/meshes/axis5-6_connector__1.stl" scale="0.001 0.001 0.001"/>
    </geometry>
  </collision>
</link>

<link name="f3Bracket__9__1">
  <inertial>
    <origin rpy="0 0 0" xyz="0.001841387427043583 0.005657241073397323 0.005657281190819818"/>
    <mass value="0.0016262220015435807"/>
    <inertia ixx="0.0" ixy="-0.0" ixz="-0.0" iyy="0.0" iyz="-0.0" izz="0.0"/>
  </inertial>
  <visual>
    <origin rpy="0 0 0" xyz="0.0035 0.088945 -0.407918"/>
    <geometry>
      <mesh filename="package://mvp_arm_6dof_description/meshes/f3Bracket__9__1.stl" scale="0.001 0.001 0.001"/>
    </geometry>
    <material name="silver"/>
  </visual>
  <collision>
    <origin rpy="0 0 0" xyz="0.0035 0.088945 -0.407918"/>
    <geometry>
      <mesh filename="package://mvp_arm_6dof_description/meshes/f3Bracket__9__1.stl" scale="0.001 0.001 0.001"/>
    </geometry>
  </collision>
</link>

<link name="f3Bracket__8__1">
  <inertial>
    <origin rpy="0 0 0" xyz="-0.0018413874273180211 0.0056572410733904815 0.005657281190812213"/>
    <mass value="0.0016262220015435807"/>
    <inertia ixx="0.0" ixy="-0.0" ixz="-0.0" iyy="0.0" iyz="-0.0" izz="0.0"/>
  </inertial>
  <visual>
    <origin rpy="0 0 0" xyz="-0.0345 0.088945 -0.407918"/>
    <geometry>
      <mesh filename="package://mvp_arm_6dof_description/meshes/f3Bracket__8__1.stl" scale="0.001 0.001 0.001"/>
    </geometry>
    <material name="silver"/>
  </visual>
  <collision>
    <origin rpy="0 0 0" xyz="-0.0345 0.088945 -0.407918"/>
    <geometry>
      <mesh filename="package://mvp_arm_6dof_description/meshes/f3Bracket__8__1.stl" scale="0.001 0.001 0.001"/>
    </geometry>
  </collision>
</link>

<link name="AX12A_servo__5__1">
  <inertial>
    <origin rpy="0 0 0" xyz="-0.013499290641083328 0.014616875823199357 0.006305478684788701"/>
    <mass value="0.3366787209762054"/>
    <inertia ixx="9.7e-05" ixy="0.0" ixz="0.0" iyy="6.6e-05" iyz="1.4e-05" izz="6.9e-05"/>
  </inertial>
  <visual>
    <origin rpy="0 0 0" xyz="-0.029 0.100258 -0.407919"/>
    <geometry>
      <mesh filename="package://mvp_arm_6dof_description/meshes/AX12A_servo__5__1.stl" scale="0.001 0.001 0.001"/>
    </geometry>
    <material name="silver"/>
  </visual>
  <collision>
    <origin rpy="0 0 0" xyz="-0.029 0.100258 -0.407919"/>
    <geometry>
      <mesh filename="package://mvp_arm_6dof_description/meshes/AX12A_servo__5__1.stl" scale="0.001 0.001 0.001"/>
    </geometry>
  </collision>
</link>

<link name="f3Bracket__10__1">
  <inertial>
    <origin rpy="0 0 0" xyz="-2.483881156312151e-13 -0.001301753641823486 -0.0013020634793980412"/>
    <mass value="0.0016262220015435807"/>
    <inertia ixx="0.0" ixy="-0.0" ixz="0.0" iyy="0.0" iyz="0.0" izz="0.0"/>
  </inertial>
  <visual>
    <origin rpy="0 0 0" xyz="-0.0155 0.10839 -0.409333"/>
    <geometry>
      <mesh filename="package://mvp_arm_6dof_description/meshes/f3Bracket__10__1.stl" scale="0.001 0.001 0.001"/>
    </geometry>
    <material name="silver"/>
  </visual>
  <collision>
    <origin rpy="0 0 0" xyz="-0.0155 0.10839 -0.409333"/>
    <geometry>
      <mesh filename="package://mvp_arm_6dof_description/meshes/f3Bracket__10__1.stl" scale="0.001 0.001 0.001"/>
    </geometry>
  </collision>
</link>

<link name="AX12A_servo__6__1">
  <inertial>
    <origin rpy="0 0 0" xyz="0.007999290640599755 -0.02865305003000715 -0.004402427555891486"/>
    <mass value="0.3366787209762054"/>
    <inertia ixx="9.7e-05" ixy="-0.0" ixz="0.0" iyy="6.6e-05" iyz="-1.4e-05" izz="6.9e-05"/>
  </inertial>
  <visual>
    <origin rpy="0 0 0" xyz="-0.0075 0.100965 -0.394131"/>
    <geometry>
      <mesh filename="package://mvp_arm_6dof_description/meshes/AX12A_servo__6__1.stl" scale="0.001 0.001 0.001"/>
    </geometry>
    <material name="silver"/>
  </visual>
  <collision>
    <origin rpy="0 0 0" xyz="-0.0075 0.100965 -0.394131"/>
    <geometry>
      <mesh filename="package://mvp_arm_6dof_description/meshes/AX12A_servo__6__1.stl" scale="0.001 0.001 0.001"/>
    </geometry>
  </collision>
</link>

<joint name="Rigid14" type="fixed">
  <origin rpy="0 0 0" xyz="-0.019 -0.01475 0.041"/>
  <parent link="base_link"/>
  <child link="f3Bracket_1"/>
</joint>

<joint name="Rigid15" type="fixed">
  <origin rpy="0 0 0" xyz="0.019 -0.01475 0.041"/>
  <parent link="base_link"/>
  <child link="f3Bracket__1__1"/>
</joint>

<joint name="Rigid16" type="fixed">
  <origin rpy="0 0 0" xyz="0.0055 0.008 0.016"/>
  <parent link="f3Bracket_1"/>
  <child link="AX12A_servo_1"/>
</joint>

<joint name="Rev17" type="continuous">
  <origin rpy="0 0 0" xyz="0.0135 0.00675 0.00475"/>
  <parent link="AX12A_servo_1"/>
  <child link="lid_1"/>
  <axis xyz="0.0 0.0 -1.0"/>
</joint>

<joint name="Rigid18" type="fixed">
  <origin rpy="0 0 0" xyz="0.0 0.0 0.005"/>
  <parent link="lid_1"/>
  <child link="f3Bracket__2__1"/>
</joint>

<joint name="Rigid19" type="fixed">
  <origin rpy="0 0 0" xyz="-0.016 -0.008 0.0055"/>
  <parent link="f3Bracket__2__1"/>
  <child link="AX12A_servo__1__1"/>
</joint>

<joint name="Rev20" type="continuous">
  <origin rpy="0 0 0" xyz="-0.00475 0.008 0.036"/>
  <parent link="AX12A_servo__1__1"/>
  <child link="f2Bracket_1"/>
  <axis xyz="1.0 -0.0 0.0"/>
</joint>

<joint name="Rigid23" type="fixed">
  <origin rpy="0 0 0" xyz="0.021 0.018709 0.018702"/>
  <parent link="f2Bracket_1"/>
  <child link="shoulderArm__1"/>
</joint>

<joint name="Rigid24" type="fixed">
  <origin rpy="0 0 0" xyz="0.0 0.106066 0.106066"/>
  <parent link="shoulderArm__1"/>
  <child link="f3Bracket__3__1"/>
</joint>

<joint name="Rigid25" type="fixed">
  <origin rpy="0 0 0" xyz="-0.015999 0.009546 -0.001768"/>
  <parent link="f3Bracket__3__1"/>
  <child link="AX12A_servo__2__1"/>
</joint>

<joint name="Rev26" type="continuous">
  <origin rpy="0 0 0" xyz="-0.00475 0.019799 0.031113"/>
  <parent link="AX12A_servo__2__1"/>
  <child link="f2Bracket__1__1"/>
  <axis xyz="1.0 0.0 -0.0"/>
</joint>

<joint name="Rigid32" type="fixed">
  <origin rpy="0 0 0" xyz="0.020999 -0.018703 0.018709"/>
  <parent link="f2Bracket__1__1"/>
  <child link="axis3-4_connector__1"/>
</joint>

<joint name="Rigid33" type="fixed">
  <origin rpy="0 0 0" xyz="0.0 -0.043487 0.016617"/>
  <parent link="axis3-4_connector__1"/>
  <child link="f3Bracket__4__1"/>
</joint>

<joint name="Rigid34" type="fixed">
  <origin rpy="0 0 0" xyz="0.0 -0.016617 0.043487"/>
  <parent link="axis3-4_connector__1"/>
  <child link="f3Bracket__5__1"/>
</joint>

<joint name="Rigid35" type="fixed">
  <origin rpy="0 0 0" xyz="0.008 -0.009545 0.001767"/>
  <parent link="f3Bracket__5__1"/>
  <child link="AX12A_servo__3__1"/>
</joint>

<joint name="Rev36" type="continuous">
  <origin rpy="0 0 0" xyz="0.00675 -0.012905 -0.006187"/>
  <parent link="AX12A_servo__3__1"/>
  <child link="f3Bracket__6__1"/>
  <axis xyz="-0.0 0.707107 -0.707107"/>
</joint>

<joint name="Rigid37" type="fixed">
  <origin rpy="0 0 0" xyz="0.0 -0.001123 0.001123"/>
  <parent link="f3Bracket__6__1"/>
  <child link="axis4ARM__1"/>
</joint>

<joint name="Rigid38" type="fixed">
  <origin rpy="0 0 0" xyz="0.0 -0.106066 0.106066"/>
  <parent link="axis4ARM__1"/>
  <child link="f3Bracket__7__1"/>
</joint>

<joint name="Rigid39" type="fixed">
  <origin rpy="0 0 0" xyz="-0.015999 -0.009546 -0.001768"/>
  <parent link="f3Bracket__7__1"/>
  <child link="AX12A_servo__4__1"/>
</joint>

<joint name="Rev40" type="continuous">
  <origin rpy="0 0 0" xyz="-0.00475 -0.019799 0.031113"/>
  <parent link="AX12A_servo__4__1"/>
  <child link="f2Bracket__2__1"/>
  <axis xyz="1.0 0.0 -0.0"/>
</joint>

<joint name="Rigid41" type="fixed">
  <origin rpy="0 0 0" xyz="0.020999 -0.018709 -0.018703"/>
  <parent link="f2Bracket__2__1"/>
  <child link="axis5-6_connector__1"/>
</joint>

<joint name="Rigid42" type="fixed">
  <origin rpy="0 0 0" xyz="-0.019 -0.030052 -0.030052"/>
  <parent link="axis5-6_connector__1"/>
  <child link="f3Bracket__9__1"/>
</joint>

<joint name="Rigid43" type="fixed">
  <origin rpy="0 0 0" xyz="0.019 -0.030052 -0.030052"/>
  <parent link="axis5-6_connector__1"/>
  <child link="f3Bracket__8__1"/>
</joint>

<joint name="Rigid44" type="fixed">
  <origin rpy="0 0 0" xyz="-0.0055 -0.011313 1e-06"/>
  <parent link="f3Bracket__8__1"/>
  <child link="AX12A_servo__5__1"/>
</joint>

<joint name="Rev45" type="continuous">
  <origin rpy="0 0 0" xyz="-0.0135 -0.008132 0.001414"/>
  <parent link="AX12A_servo__5__1"/>
  <child link="f3Bracket__10__1"/>
  <axis xyz="-0.0 -0.707107 -0.707107"/>
</joint>

<joint name="Rigid46" type="fixed">
  <origin rpy="0 0 0" xyz="-0.008 0.007425 -0.015202"/>
  <parent link="f3Bracket__10__1"/>
  <child link="AX12A_servo__6__1"/>
</joint>

</robot>
