<?xml version="1.0" ?>
<robot name="mvp_arm_4dof_v2" xmlns:xacro="http://www.ros.org/wiki/xacro">

<xacro:include filename="$(find mvp_arm_4dof_v2_description)/urdf/materials.xacro" />
<xacro:include filename="$(find mvp_arm_4dof_v2_description)/urdf/mvp_arm_4dof_v2.trans" />
<xacro:include filename="$(find mvp_arm_4dof_v2_description)/urdf/mvp_arm_4dof_v2.gazebo" />
<link name="base_link">
  <inertial>
    <origin rpy="0 0 0" xyz="-0.005977131812596751 0.0034085511625430998 0.04750670712014007"/>
    <mass value="2.456555111592732"/>
    <inertia ixx="0.00924" ixy="-9.9e-05" ixz="1.9e-05" iyy="0.009207" iyz="-5e-06" izz="0.009587"/>
  </inertial>
  <visual>
    <origin rpy="0 0 0" xyz="0 0 0"/>
    <geometry>
      <mesh filename="package://mvp_arm_4dof_v2_description/meshes/base_link.stl" scale="0.001 0.001 0.001"/>
    </geometry>
    <material name="silver"/>
  </visual>
  <collision>
    <origin rpy="0 0 0" xyz="0 0 0"/>
    <geometry>
      <mesh filename="package://mvp_arm_4dof_v2_description/meshes/base_link.stl" scale="0.001 0.001 0.001"/>
    </geometry>
  </collision>
</link>

<link name="link_1_v1_1">
  <inertial>
    <origin rpy="0 0 0" xyz="-0.000875606257567706 0.05779240378793745 0.1272041561930602"/>
    <mass value="0.5341010747394327"/>
    <inertia ixx="0.000353" ixy="-7e-06" ixz="4.8e-05" iyy="0.000457" iyz="4.2e-05" izz="0.000429"/>
  </inertial>
  <visual>
    <origin rpy="0 0 0" xyz="0.006662 0.059816 -0.021297"/>
    <geometry>
      <mesh filename="package://mvp_arm_4dof_v2_description/meshes/link_1_v1_1.stl" scale="0.001 0.001 0.001"/>
    </geometry>
    <material name="silver"/>
  </visual>
  <collision>
    <origin rpy="0 0 0" xyz="0.006662 0.059816 -0.021297"/>
    <geometry>
      <mesh filename="package://mvp_arm_4dof_v2_description/meshes/link_1_v1_1.stl" scale="0.001 0.001 0.001"/>
    </geometry>
  </collision>
</link>

<link name="link_2_v1_1">
  <inertial>
    <origin rpy="0 0 0" xyz="0.04130764391702361 0.10840323821397341 0.274192235286784"/>
    <mass value="0.5015278384318742"/>
    <inertia ixx="0.00084" ixy="-1e-06" ixz="-1.9e-05" iyy="0.000878" iyz="-3e-06" izz="7.2e-05"/>
  </inertial>
  <visual>
    <origin rpy="0 0 0" xyz="0.060287 0.100021 0.04361"/>
    <geometry>
      <mesh filename="package://mvp_arm_4dof_v2_description/meshes/link_2_v1_1.stl" scale="0.001 0.001 0.001"/>
    </geometry>
    <material name="silver"/>
  </visual>
  <collision>
    <origin rpy="0 0 0" xyz="0.060287 0.100021 0.04361"/>
    <geometry>
      <mesh filename="package://mvp_arm_4dof_v2_description/meshes/link_2_v1_1.stl" scale="0.001 0.001 0.001"/>
    </geometry>
  </collision>
</link>

<link name="link_4_v1_1">
  <inertial>
    <origin rpy="0 0 0" xyz="0.12518707402793333 0.2106331714250435 0.11869023510237614"/>
    <mass value="0.1295112121194818"/>
    <inertia ixx="2e-05" ixy="4e-06" ixz="0.0" iyy="4e-05" iyz="-1e-06" izz="3.1e-05"/>
  </inertial>
  <visual>
    <origin rpy="0 0 0" xyz="0.249835 0.214413 -0.178867"/>
    <geometry>
      <mesh filename="package://mvp_arm_4dof_v2_description/meshes/link_4_v1_1.stl" scale="0.001 0.001 0.001"/>
    </geometry>
    <material name="silver"/>
  </visual>
  <collision>
    <origin rpy="0 0 0" xyz="0.249835 0.214413 -0.178867"/>
    <geometry>
      <mesh filename="package://mvp_arm_4dof_v2_description/meshes/link_4_v1_1.stl" scale="0.001 0.001 0.001"/>
    </geometry>
  </collision>
</link>

<link name="link_3_v1_1">
  <inertial>
    <origin rpy="0 0 0" xyz="0.10382144706659589 0.16294918152414598 0.1398754495178515"/>
    <mass value="0.39461490281663475"/>
    <inertia ixx="7.5e-05" ixy="-1.2e-05" ixz="2.2e-05" iyy="0.000456" iyz="1e-06" izz="0.000427"/>
  </inertial>
  <visual>
    <origin rpy="0 0 0" xyz="0.160151 0.170356 -0.153996"/>
    <geometry>
      <mesh filename="package://mvp_arm_4dof_v2_description/meshes/link_3_v1_1.stl" scale="0.001 0.001 0.001"/>
    </geometry>
    <material name="silver"/>
  </visual>
  <collision>
    <origin rpy="0 0 0" xyz="0.160151 0.170356 -0.153996"/>
    <geometry>
      <mesh filename="package://mvp_arm_4dof_v2_description/meshes/link_3_v1_1.stl" scale="0.001 0.001 0.001"/>
    </geometry>
  </collision>
</link>

<link name="gripper_base_1">
  <inertial>
    <origin rpy="0 0 0" xyz="-0.17209556312670746 0.011362474994589363 0.368203383741293"/>
    <mass value="0.12341304164534714"/>
    <inertia ixx="2.2e-05" ixy="-1.1e-05" ixz="1.4e-05" iyy="5.7e-05" iyz="4e-06" izz="6.2e-05"/>
  </inertial>
  <visual>
    <origin rpy="0 0 0" xyz="-0.014 0.009 0.063"/>
    <geometry>
      <mesh filename="package://mvp_arm_4dof_v2_description/meshes/gripper_base_1.stl" scale="0.001 0.001 0.001"/>
    </geometry>
    <material name="silver"/>
  </visual>
  <collision>
    <origin rpy="0 0 0" xyz="-0.014 0.009 0.063"/>
    <geometry>
      <mesh filename="package://mvp_arm_4dof_v2_description/meshes/gripper_base_1.stl" scale="0.001 0.001 0.001"/>
    </geometry>
  </collision>
</link>

<link name="right_gear_1">
  <inertial>
    <origin rpy="0 0 0" xyz="-0.16318588589445696 0.01896748362344826 0.3197389743115331"/>
    <mass value="0.020736664284343446"/>
    <inertia ixx="3e-06" ixy="0.0" ixz="0.0" iyy="1e-06" iyz="0.0" izz="4e-06"/>
  </inertial>
  <visual>
    <origin rpy="0 0 0" xyz="0.010106 0.0 -0.0"/>
    <geometry>
      <mesh filename="package://mvp_arm_4dof_v2_description/meshes/right_gear_1.stl" scale="0.001 0.001 0.001"/>
    </geometry>
    <material name="silver"/>
  </visual>
  <collision>
    <origin rpy="0 0 0" xyz="0.010106 0.0 -0.0"/>
    <geometry>
      <mesh filename="package://mvp_arm_4dof_v2_description/meshes/right_gear_1.stl" scale="0.001 0.001 0.001"/>
    </geometry>
  </collision>
</link>

<link name="right_finger_1">
  <inertial>
    <origin rpy="0 0 0" xyz="-0.20320923622759174 0.032712841198655945 0.3196412140981905"/>
    <mass value="0.04236978910676512"/>
    <inertia ixx="1e-06" ixy="-2e-06" ixz="1e-06" iyy="1.3e-05" iyz="0.0" izz="1.3e-05"/>
  </inertial>
  <visual>
    <origin rpy="0 0 0" xyz="-0.0 -0.005 0.005"/>
    <geometry>
      <mesh filename="package://mvp_arm_4dof_v2_description/meshes/right_finger_1.stl" scale="0.001 0.001 0.001"/>
    </geometry>
    <material name="silver"/>
  </visual>
  <collision>
    <origin rpy="0 0 0" xyz="-0.0 -0.005 0.005"/>
    <geometry>
      <mesh filename="package://mvp_arm_4dof_v2_description/meshes/right_finger_1.stl" scale="0.001 0.001 0.001"/>
    </geometry>
  </collision>
</link>

<link name="left_gear_1">
  <inertial>
    <origin rpy="0 0 0" xyz="-0.16076751237208856 -0.01902423008348852 0.3210979042613271"/>
    <mass value="0.020141998404349184"/>
    <inertia ixx="3e-06" ixy="0.0" ixz="0.0" iyy="1e-06" iyz="0.0" izz="3e-06"/>
  </inertial>
  <visual>
    <origin rpy="0 0 0" xyz="0.010106 0.0 -0.0"/>
    <geometry>
      <mesh filename="package://mvp_arm_4dof_v2_description/meshes/left_gear_1.stl" scale="0.001 0.001 0.001"/>
    </geometry>
    <material name="silver"/>
  </visual>
  <collision>
    <origin rpy="0 0 0" xyz="0.010106 0.0 -0.0"/>
    <geometry>
      <mesh filename="package://mvp_arm_4dof_v2_description/meshes/left_gear_1.stl" scale="0.001 0.001 0.001"/>
    </geometry>
  </collision>
</link>

<link name="left_finger_1">
  <inertial>
    <origin rpy="0 0 0" xyz="-0.2018512033439198 -0.04322555745722514 0.3220355383030479"/>
    <mass value="0.04236978910676512"/>
    <inertia ixx="1e-06" ixy="2e-06" ixz="1e-06" iyy="1.3e-05" iyz="-0.0" izz="1.3e-05"/>
  </inertial>
  <visual>
    <origin rpy="0 0 0" xyz="-0.0085 -0.005 0.005"/>
    <geometry>
      <mesh filename="package://mvp_arm_4dof_v2_description/meshes/left_finger_1.stl" scale="0.001 0.001 0.001"/>
    </geometry>
    <material name="silver"/>
  </visual>
  <collision>
    <origin rpy="0 0 0" xyz="-0.0085 -0.005 0.005"/>
    <geometry>
      <mesh filename="package://mvp_arm_4dof_v2_description/meshes/left_finger_1.stl" scale="0.001 0.001 0.001"/>
    </geometry>
  </collision>
</link>

<link name="left_link_1">
  <inertial>
    <origin rpy="0 0 0" xyz="-0.22006208615248604 -0.02026473802384253 0.3223127777853347"/>
    <mass value="0.006270284943499798"/>
    <inertia ixx="1e-06" ixy="0.0" ixz="-0.0" iyy="0.0" iyz="0.0" izz="1e-06"/>
  </inertial>
  <visual>
    <origin rpy="0 0 0" xyz="-0.031 -0.0 -0.0"/>
    <geometry>
      <mesh filename="package://mvp_arm_4dof_v2_description/meshes/left_link_1.stl" scale="0.001 0.001 0.001"/>
    </geometry>
    <material name="silver"/>
  </visual>
  <collision>
    <origin rpy="0 0 0" xyz="-0.031 -0.0 -0.0"/>
    <geometry>
      <mesh filename="package://mvp_arm_4dof_v2_description/meshes/left_link_1.stl" scale="0.001 0.001 0.001"/>
    </geometry>
  </collision>
</link>

<link name="right_link_1">
  <inertial>
    <origin rpy="0 0 0" xyz="-0.22510923661252874 0.020340317264004194 0.3210181519632032"/>
    <mass value="0.006270284943499798"/>
    <inertia ixx="1e-06" ixy="0.0" ixz="-0.0" iyy="0.0" iyz="0.0" izz="1e-06"/>
  </inertial>
  <visual>
    <origin rpy="0 0 0" xyz="-0.031 -0.0 -0.0"/>
    <geometry>
      <mesh filename="package://mvp_arm_4dof_v2_description/meshes/right_link_1.stl" scale="0.001 0.001 0.001"/>
    </geometry>
    <material name="silver"/>
  </visual>
  <collision>
    <origin rpy="0 0 0" xyz="-0.031 -0.0 -0.0"/>
    <geometry>
      <mesh filename="package://mvp_arm_4dof_v2_description/meshes/right_link_1.stl" scale="0.001 0.001 0.001"/>
    </geometry>
  </collision>
</link>

<link name="left_link_1">
  <inertial>
    <origin rpy="0 0 0" xyz="-0.18906208615248604 -0.02026473802384253 0.3223127777853347"/>
    <mass value="0.006270284943499798"/>
    <inertia ixx="1e-06" ixy="0.0" ixz="-0.0" iyy="0.0" iyz="0.0" izz="1e-06"/>
  </inertial>
  <visual>
    <origin rpy="0 0 0" xyz="-0.0 -0.0 -0.0"/>
    <geometry>
      <mesh filename="package://mvp_arm_4dof_v2_description/meshes/left_link_1.stl" scale="0.001 0.001 0.001"/>
    </geometry>
    <material name="silver"/>
  </visual>
  <collision>
    <origin rpy="0 0 0" xyz="-0.0 -0.0 -0.0"/>
    <geometry>
      <mesh filename="package://mvp_arm_4dof_v2_description/meshes/left_link_1.stl" scale="0.001 0.001 0.001"/>
    </geometry>
  </collision>
</link>

<link name="right_finger_1">
  <inertial>
    <origin rpy="0 0 0" xyz="-0.20320923622759174 0.032712841198655945 0.34164121409819054"/>
    <mass value="0.04236978910676512"/>
    <inertia ixx="1e-06" ixy="-2e-06" ixz="1e-06" iyy="1.3e-05" iyz="0.0" izz="1.3e-05"/>
  </inertial>
  <visual>
    <origin rpy="0 0 0" xyz="-0.0 -0.005 0.027"/>
    <geometry>
      <mesh filename="package://mvp_arm_4dof_v2_description/meshes/right_finger_1.stl" scale="0.001 0.001 0.001"/>
    </geometry>
    <material name="silver"/>
  </visual>
  <collision>
    <origin rpy="0 0 0" xyz="-0.0 -0.005 0.027"/>
    <geometry>
      <mesh filename="package://mvp_arm_4dof_v2_description/meshes/right_finger_1.stl" scale="0.001 0.001 0.001"/>
    </geometry>
  </collision>
</link>

<joint name="Rev1" type="continuous">
  <origin rpy="0 0 0" xyz="-0.006662 -0.059816 0.021297"/>
  <parent link="base_link"/>
  <child link="link_1_v1_1"/>
  <axis xyz="-0.002854 0.005633 0.99998"/>
</joint>

<joint name="Rev2" type="continuous">
  <origin rpy="0 0 0" xyz="-0.053625 -0.040205 -0.064907"/>
  <parent link="link_1_v1_1"/>
  <child link="link_2_v1_1"/>
  <axis xyz="-0.025335 0.999663 -0.005703"/>
</joint>

<joint name="Rigid1" type="fixed">
  <origin rpy="0 0 0" xyz="-0.089684 -0.044057 0.024871"/>
  <parent link="link_3_v1_1"/>
  <child link="link_4_v1_1"/>
</joint>

<joint name="Rev3" type="continuous">
  <origin rpy="0 0 0" xyz="-0.099864 -0.070335 0.197606"/>
  <parent link="link_2_v1_1"/>
  <child link="link_3_v1_1"/>
  <axis xyz="0.025335 -0.999663 0.005703"/>
</joint>

<joint name="Rev4" type="continuous">
  <origin rpy="0 0 0" xyz="0.263835 0.205413 -0.241867"/>
  <parent link="link_4_v1_1"/>
  <child link="gripper_base_1"/>
  <axis xyz="0.027296 -0.998903 0.038055"/>
</joint>

<joint name="G_Rev2" type="continuous">
  <origin rpy="0 0 0" xyz="-0.024106 0.009 0.063"/>
  <parent link="gripper_base_1"/>
  <child link="right_gear_1"/>
  <axis xyz="0.063894 0.039735 0.997165"/>
</joint>

<joint name="G_Rev3" type="continuous">
  <origin rpy="0 0 0" xyz="0.010106 0.005 -0.027"/>
  <parent link="right_gear_1"/>
  <child link="right_finger_1"/>
  <axis xyz="0.063894 0.039735 0.997165"/>
</joint>

<joint name="G_Rev1" type="continuous">
  <origin rpy="0 0 0" xyz="-0.024106 0.009 0.063"/>
  <parent link="gripper_base_1"/>
  <child link="left_gear_1"/>
  <axis xyz="0.063894 0.039735 0.997165"/>
</joint>

<joint name="G_Rev4" type="continuous">
  <origin rpy="0 0 0" xyz="0.018606 0.005 -0.005"/>
  <parent link="left_gear_1"/>
  <child link="left_finger_1"/>
  <axis xyz="0.063894 0.039735 0.997165"/>
</joint>

<joint name="G_Rev5" type="continuous">
  <origin rpy="0 0 0" xyz="-0.014 0.009 0.063"/>
  <parent link="gripper_base_1"/>
  <child link="left_link_1"/>
  <axis xyz="0.063894 0.039735 0.997165"/>
</joint>

<joint name="G_Rev6" type="continuous">
  <origin rpy="0 0 0" xyz="0.017 0.009 0.063"/>
  <parent link="gripper_base_1"/>
  <child link="right_link_1"/>
  <axis xyz="0.063894 0.039735 0.997165"/>
</joint>

<joint name="G_Rev7" type="continuous">
  <origin rpy="0 0 0" xyz="-0.0085 -0.005 0.005"/>
  <parent link="left_finger_1"/>
  <child link="left_link_1"/>
  <axis xyz="0.063894 0.039735 0.997165"/>
</joint>

<joint name="G_Rev8" type="continuous">
  <origin rpy="0 0 0" xyz="-0.031 0.005 -0.027"/>
  <parent link="right_link_1"/>
  <child link="right_finger_1"/>
  <axis xyz="0.063894 0.039735 0.997165"/>
</joint>

</robot>
