<?xml version="1.0" encoding="utf-8"?>
<!-- =================================================================================== -->
<!-- |    This document was autogenerated by xacro from robot_arm_urdf_v1.xacro        | -->
<!-- |    EDITING THIS FILE BY HAND IS NOT RECOMMENDED                                 | -->
<!-- =================================================================================== -->
<robot name="robot_arm_urdf_v1">
  <material name="silver">
    <color rgba="0.700 0.700 0.700 1.000"/>
  </material>
  <transmission name="Rev1_tran">
    <type>transmission_interface/SimpleTransmission</type>
    <joint name="Rev1">
      <hardwareInterface>hardware_interface/EffortJointInterface</hardwareInterface>
    </joint>
    <actuator name="Rev1_actr">
      <hardwareInterface>hardware_interface/EffortJointInterface</hardwareInterface>
      <mechanicalReduction>1</mechanicalReduction>
    </actuator>
  </transmission>
  <transmission name="Rev2_tran">
    <type>transmission_interface/SimpleTransmission</type>
    <joint name="Rev2">
      <hardwareInterface>hardware_interface/EffortJointInterface</hardwareInterface>
    </joint>
    <actuator name="Rev2_actr">
      <hardwareInterface>hardware_interface/EffortJointInterface</hardwareInterface>
      <mechanicalReduction>1</mechanicalReduction>
    </actuator>
  </transmission>
  <transmission name="Rev6_tran">
    <type>transmission_interface/SimpleTransmission</type>
    <joint name="Rev6">
      <hardwareInterface>hardware_interface/EffortJointInterface</hardwareInterface>
    </joint>
    <actuator name="Rev6_actr">
      <hardwareInterface>hardware_interface/EffortJointInterface</hardwareInterface>
      <mechanicalReduction>1</mechanicalReduction>
    </actuator>
  </transmission>
  <transmission name="Rev7_tran">
    <type>transmission_interface/SimpleTransmission</type>
    <joint name="Rev7">
      <hardwareInterface>hardware_interface/EffortJointInterface</hardwareInterface>
    </joint>
    <actuator name="Rev7_actr">
      <hardwareInterface>hardware_interface/EffortJointInterface</hardwareInterface>
      <mechanicalReduction>1</mechanicalReduction>
    </actuator>
  </transmission>
  <transmission name="Rev5_tran">
    <type>transmission_interface/SimpleTransmission</type>
    <joint name="Rev5">
      <hardwareInterface>hardware_interface/EffortJointInterface</hardwareInterface>
    </joint>
    <actuator name="Rev5_actr">
      <hardwareInterface>hardware_interface/EffortJointInterface</hardwareInterface>
      <mechanicalReduction>1</mechanicalReduction>
    </actuator>
  </transmission>
  <transmission name="Rev4_tran">
    <type>transmission_interface/SimpleTransmission</type>
    <joint name="Rev4">
      <hardwareInterface>hardware_interface/EffortJointInterface</hardwareInterface>
    </joint>
    <actuator name="Rev4_actr">
      <hardwareInterface>hardware_interface/EffortJointInterface</hardwareInterface>
      <mechanicalReduction>1</mechanicalReduction>
    </actuator>
  </transmission>
  <transmission name="Rev3_tran">
    <type>transmission_interface/SimpleTransmission</type>
    <joint name="Rev3">
      <hardwareInterface>hardware_interface/EffortJointInterface</hardwareInterface>
    </joint>
    <actuator name="Rev3_actr">
      <hardwareInterface>hardware_interface/EffortJointInterface</hardwareInterface>
      <mechanicalReduction>1</mechanicalReduction>
    </actuator>
  </transmission>
  <gazebo>
    <plugin filename="libgazebo_ros_control.so" name="control"/>
  </gazebo>
  <gazebo reference="base_link">
    <material>Gazebo/Silver</material>
    <mu1>0.2</mu1>
    <mu2>0.2</mu2>
    <selfCollide>true</selfCollide>
    <gravity>true</gravity>
  </gazebo>
  <gazebo reference="link_1_v1_1">
    <material>Gazebo/Silver</material>
    <mu1>0.2</mu1>
    <mu2>0.2</mu2>
    <selfCollide>true</selfCollide>
  </gazebo>
  <gazebo reference="link_2_v1_1">
    <material>Gazebo/Silver</material>
    <mu1>0.2</mu1>
    <mu2>0.2</mu2>
    <selfCollide>true</selfCollide>
  </gazebo>
  <gazebo reference="gear2_v1_1">
    <material>Gazebo/Silver</material>
    <mu1>0.2</mu1>
    <mu2>0.2</mu2>
    <selfCollide>true</selfCollide>
  </gazebo>
  <gazebo reference="gear1_v1_1">
    <material>Gazebo/Silver</material>
    <mu1>0.2</mu1>
    <mu2>0.2</mu2>
    <selfCollide>true</selfCollide>
  </gazebo>
  <gazebo reference="gripper_base_v1_1">
    <material>Gazebo/Silver</material>
    <mu1>0.2</mu1>
    <mu2>0.2</mu2>
    <selfCollide>true</selfCollide>
  </gazebo>
  <gazebo reference="link_4_v1_1">
    <material>Gazebo/Silver</material>
    <mu1>0.2</mu1>
    <mu2>0.2</mu2>
    <selfCollide>true</selfCollide>
  </gazebo>
  <gazebo reference="link_3_v1_1">
    <material>Gazebo/Silver</material>
    <mu1>0.2</mu1>
    <mu2>0.2</mu2>
    <selfCollide>true</selfCollide>
  </gazebo>
  <link name="base_link">
    <visual>
      <origin rpy="0 0 0" xyz="0 0 0"/>
      <geometry>
        <mesh filename="package://robot_arm_urdf_v1_description/meshes/base_link.stl" scale="0.001 0.001 0.001"/>
      </geometry>
      <material name="silver"/>
    </visual>
    <collision>
      <origin rpy="0 0 0" xyz="0 0 0"/>
      <geometry>
        <mesh filename="package://robot_arm_urdf_v1_description/meshes/base_link.stl" scale="0.001 0.001 0.001"/>
      </geometry>
    </collision>
  </link>
  <link name="link_1_v1_1">
    <visual>
      <origin rpy="0 0 0" xyz="0.006279 -0.004346 -0.056179"/>
      <geometry>
        <mesh filename="package://robot_arm_urdf_v1_description/meshes/link_1_v1_1.stl" scale="0.001 0.001 0.001"/>
      </geometry>
      <material name="silver"/>
    </visual>
    <collision>
      <origin rpy="0 0 0" xyz="0.006279 -0.004346 -0.056179"/>
      <geometry>
        <mesh filename="package://robot_arm_urdf_v1_description/meshes/link_1_v1_1.stl" scale="0.001 0.001 0.001"/>
      </geometry>
    </collision>
  </link>
  <link name="link_2_v1_1">
    <visual>
      <origin rpy="0 0 0" xyz="0.014548 0.007395 -0.096499"/>
      <geometry>
        <mesh filename="package://robot_arm_urdf_v1_description/meshes/link_2_v1_1.stl" scale="0.001 0.001 0.001"/>
      </geometry>
      <material name="silver"/>
    </visual>
    <collision>
      <origin rpy="0 0 0" xyz="0.014548 0.007395 -0.096499"/>
      <geometry>
        <mesh filename="package://robot_arm_urdf_v1_description/meshes/link_2_v1_1.stl" scale="0.001 0.001 0.001"/>
      </geometry>
    </collision>
  </link>
  <link name="gear2_v1_1">
    <visual>
      <origin rpy="0 0 0" xyz="0.075306 0.071811 -0.286865"/>
      <geometry>
        <mesh filename="package://robot_arm_urdf_v1_description/meshes/gear2_v1_1.stl" scale="0.001 0.001 0.001"/>
      </geometry>
      <material name="silver"/>
    </visual>
    <collision>
      <origin rpy="0 0 0" xyz="0.075306 0.071811 -0.286865"/>
      <geometry>
        <mesh filename="package://robot_arm_urdf_v1_description/meshes/gear2_v1_1.stl" scale="0.001 0.001 0.001"/>
      </geometry>
    </collision>
  </link>
  <link name="gear1_v1_1">
    <visual>
      <origin rpy="0 0 0" xyz="0.092897 0.051478 -0.286019"/>
      <geometry>
        <mesh filename="package://robot_arm_urdf_v1_description/meshes/gear1_v1_1.stl" scale="0.001 0.001 0.001"/>
      </geometry>
      <material name="silver"/>
    </visual>
    <collision>
      <origin rpy="0 0 0" xyz="0.092897 0.051478 -0.286019"/>
      <geometry>
        <mesh filename="package://robot_arm_urdf_v1_description/meshes/gear1_v1_1.stl" scale="0.001 0.001 0.001"/>
      </geometry>
    </collision>
  </link>
  <link name="gripper_base_v1_1">
    <visual>
      <origin rpy="0 0 0" xyz="0.056533 0.032128 -0.2811"/>
      <geometry>
        <mesh filename="package://robot_arm_urdf_v1_description/meshes/gripper_base_v1_1.stl" scale="0.001 0.001 0.001"/>
      </geometry>
      <material name="silver"/>
    </visual>
    <collision>
      <origin rpy="0 0 0" xyz="0.056533 0.032128 -0.2811"/>
      <geometry>
        <mesh filename="package://robot_arm_urdf_v1_description/meshes/gripper_base_v1_1.stl" scale="0.001 0.001 0.001"/>
      </geometry>
    </collision>
  </link>
  <link name="link_4_v1_1">
    <visual>
      <origin rpy="0 0 0" xyz="0.032792 0.030982 -0.260123"/>
      <geometry>
        <mesh filename="package://robot_arm_urdf_v1_description/meshes/link_4_v1_1.stl" scale="0.001 0.001 0.001"/>
      </geometry>
      <material name="silver"/>
    </visual>
    <collision>
      <origin rpy="0 0 0" xyz="0.032792 0.030982 -0.260123"/>
      <geometry>
        <mesh filename="package://robot_arm_urdf_v1_description/meshes/link_4_v1_1.stl" scale="0.001 0.001 0.001"/>
      </geometry>
    </collision>
  </link>
  <link name="link_3_v1_1">
    <inertial>
      <origin rpy="0 0 0" xyz="-0.018927647949470994 -0.025147663874973945 0.02464919326183307"/>
      <mass value="0.39461490281663475"/>
      <inertia ixx="0.000313" ixy="-0.00012" ixz="0.000133" iyy="0.000356" iyz="0.000111" izz="0.000289"/>
    </inertial>
    <visual>
      <origin rpy="0 0 0" xyz="-0.019036 -0.021381 -0.208052"/>
      <geometry>
        <mesh filename="package://robot_arm_urdf_v1_description/meshes/link_3_v1_1.stl" scale="0.001 0.001 0.001"/>
      </geometry>
      <material name="silver"/>
    </visual>
    <collision>
      <origin rpy="0 0 0" xyz="-0.019036 -0.021381 -0.208052"/>
      <geometry>
        <mesh filename="package://robot_arm_urdf_v1_description/meshes/link_3_v1_1.stl" scale="0.001 0.001 0.001"/>
      </geometry>
    </collision>
  </link>
  <joint name="Rev1" type="continuous">
    <origin rpy="0 0 0" xyz="-0.006279 0.004346 0.056179"/>
    <parent link="base_link"/>
    <child link="link_1_v1_1"/>
    <axis xyz="-0.002854 0.005633 0.99998"/>
  </joint>
  <joint name="Rev2" type="continuous">
    <origin rpy="0 0 0" xyz="-0.008269 -0.011741 0.04032"/>
    <parent link="link_1_v1_1"/>
    <child link="link_2_v1_1"/>
    <axis xyz="-0.638789 0.769358 -0.006157"/>
  </joint>
  <joint name="Rev6" type="continuous">
    <origin rpy="0 0 0" xyz="-0.018773 -0.039683 0.005765"/>
    <parent link="gripper_base_v1_1"/>
    <child link="gear2_v1_1"/>
    <axis xyz="-0.188117 -0.122221 0.974512"/>
  </joint>
  <joint name="Rev7" type="continuous">
    <origin rpy="0 0 0" xyz="-0.036364 -0.01935 0.004919"/>
    <parent link="gripper_base_v1_1"/>
    <child link="gear1_v1_1"/>
    <axis xyz="-0.188117 -0.122221 0.974512"/>
  </joint>
  <joint name="Rev5" type="continuous">
    <origin rpy="0 0 0" xyz="-0.023741 -0.001146 0.020977"/>
    <parent link="link_4_v1_1"/>
    <child link="gripper_base_v1_1"/>
    <axis xyz="0.653959 -0.755876 0.031439"/>
  </joint>
  <joint name="Rev4" type="continuous">
    <origin rpy="0 0 0" xyz="-0.051828 -0.052363 0.052071"/>
    <parent link="link_3_v1_1"/>
    <child link="link_4_v1_1"/>
    <axis xyz="-0.602598 -0.495323 0.625725"/>
  </joint>
  <joint name="Rev3" type="continuous">
    <origin rpy="0 0 0" xyz="0.033584 0.028776 0.111553"/>
    <parent link="link_2_v1_1"/>
    <child link="link_3_v1_1"/>
    <axis xyz="0.638789 -0.769358 0.006157"/>
  </joint>
</robot>
