<?xml version="1.0" ?>
<robot name="mvp_arm_6dof_v2" xmlns:xacro="http://www.ros.org/wiki/xacro">

<xacro:include filename="$(find mvp_arm_6dof_v2_description)/urdf/materials.xacro" />
<xacro:include filename="$(find mvp_arm_6dof_v2_description)/urdf/mvp_arm_6dof_v2.trans" />
<xacro:include filename="$(find mvp_arm_6dof_v2_description)/urdf/mvp_arm_6dof_v2.gazebo" />
<link name="base_link">
  <inertial>
    <origin rpy="0 0 0" xyz="-0.0002685563857322659 -0.004117383840236073 0.09720599739360383"/>
    <mass value="0.2255222028913783"/>
    <inertia ixx="0.000625" ixy="-0.0" ixz="-1.3e-05" iyy="0.000615" iyz="0.0" izz="0.001121"/>
  </inertial>
  <visual>
    <origin rpy="0 0 0" xyz="0 0 0"/>
    <geometry>
      <mesh filename="package://mvp_arm_6dof_v2_description/meshes/base_link.stl" scale="0.001 0.001 0.001"/>
    </geometry>
    <material name="silver"/>
  </visual>
  <collision>
    <origin rpy="0 0 0" xyz="0 0 0"/>
    <geometry>
      <mesh filename="package://mvp_arm_6dof_v2_description/meshes/base_link.stl" scale="0.001 0.001 0.001"/>
    </geometry>
  </collision>
</link>

<link name="Servo_Rotator__1__1">
  <inertial>
    <origin rpy="0 0 0" xyz="4.696790787805938e-05 2.736599626973436e-05 -0.0022484802383110902"/>
    <mass value="0.012286224598738087"/>
    <inertia ixx="0.0" ixy="0.0" ixz="-0.0" iyy="0.0" iyz="-0.0" izz="1e-06"/>
  </inertial>
  <visual>
    <origin rpy="0 0 0" xyz="-0.278678 0.002272 -0.30869"/>
    <geometry>
      <mesh filename="package://mvp_arm_6dof_v2_description/meshes/Servo_Rotator__1__1.stl" scale="0.001 0.001 0.001"/>
    </geometry>
    <material name="silver"/>
  </visual>
  <collision>
    <origin rpy="0 0 0" xyz="-0.278678 0.002272 -0.30869"/>
    <geometry>
      <mesh filename="package://mvp_arm_6dof_v2_description/meshes/Servo_Rotator__1__1.stl" scale="0.001 0.001 0.001"/>
    </geometry>
  </collision>
</link>

<link name="Servo_Rotator__2__1">
  <inertial>
    <origin rpy="0 0 0" xyz="3.197445282709932e-07 -0.002249396881839328 1.0236701699029016e-05"/>
    <mass value="0.012286224598738087"/>
    <inertia ixx="0.0" ixy="-0.0" ixz="0.0" iyy="1e-06" iyz="-0.0" izz="0.0"/>
  </inertial>
  <visual>
    <origin rpy="0 0 0" xyz="-0.214785 0.018149 -0.391636"/>
    <geometry>
      <mesh filename="package://mvp_arm_6dof_v2_description/meshes/Servo_Rotator__2__1.stl" scale="0.001 0.001 0.001"/>
    </geometry>
    <material name="silver"/>
  </visual>
  <collision>
    <origin rpy="0 0 0" xyz="-0.214785 0.018149 -0.391636"/>
    <geometry>
      <mesh filename="package://mvp_arm_6dof_v2_description/meshes/Servo_Rotator__2__1.stl" scale="0.001 0.001 0.001"/>
    </geometry>
  </collision>
</link>

<link name="Servo__3__1">
  <inertial>
    <origin rpy="0 0 0" xyz="0.023084439447248556 0.01543302398482891 -0.007466520807867916"/>
    <mass value="0.32411536495008075"/>
    <inertia ixx="5e-05" ixy="-2e-06" ixz="-1e-06" iyy="7.9e-05" iyz="0.0" izz="9.1e-05"/>
  </inertial>
  <visual>
    <origin rpy="0 0 0" xyz="-0.178587 0.017871 -0.398684"/>
    <geometry>
      <mesh filename="package://mvp_arm_6dof_v2_description/meshes/Servo__3__1.stl" scale="0.001 0.001 0.001"/>
    </geometry>
    <material name="silver"/>
  </visual>
  <collision>
    <origin rpy="0 0 0" xyz="-0.178587 0.017871 -0.398684"/>
    <geometry>
      <mesh filename="package://mvp_arm_6dof_v2_description/meshes/Servo__3__1.stl" scale="0.001 0.001 0.001"/>
    </geometry>
  </collision>
</link>

<link name="Servo__2__1">
  <inertial>
    <origin rpy="0 0 0" xyz="-0.01645020938837613 -0.008616049568100454 -0.0196927644624752"/>
    <mass value="0.32411536495008075"/>
    <inertia ixx="7.9e-05" ixy="0.0" ixz="-1e-06" iyy="9.1e-05" iyz="-0.0" izz="5e-05"/>
  </inertial>
  <visual>
    <origin rpy="0 0 0" xyz="-0.232814 -0.00619 -0.356393"/>
    <geometry>
      <mesh filename="package://mvp_arm_6dof_v2_description/meshes/Servo__2__1.stl" scale="0.001 0.001 0.001"/>
    </geometry>
    <material name="silver"/>
  </visual>
  <collision>
    <origin rpy="0 0 0" xyz="-0.232814 -0.00619 -0.356393"/>
    <geometry>
      <mesh filename="package://mvp_arm_6dof_v2_description/meshes/Servo__2__1.stl" scale="0.001 0.001 0.001"/>
    </geometry>
  </collision>
</link>

<link name="Servo_Rotator__3__1">
  <inertial>
    <origin rpy="0 0 0" xyz="0.002249048184267688 1.7890290807034276e-07 4.676532271863376e-05"/>
    <mass value="0.012286224598738087"/>
    <inertia ixx="1e-06" ixy="0.0" ixz="0.0" iyy="0.0" iyz="0.0" izz="0.0"/>
  </inertial>
  <visual>
    <origin rpy="0 0 0" xyz="-0.232349 0.002482 -0.323916"/>
    <geometry>
      <mesh filename="package://mvp_arm_6dof_v2_description/meshes/Servo_Rotator__3__1.stl" scale="0.001 0.001 0.001"/>
    </geometry>
    <material name="silver"/>
  </visual>
  <collision>
    <origin rpy="0 0 0" xyz="-0.232349 0.002482 -0.323916"/>
    <geometry>
      <mesh filename="package://mvp_arm_6dof_v2_description/meshes/Servo_Rotator__3__1.stl" scale="0.001 0.001 0.001"/>
    </geometry>
  </collision>
</link>

<link name="Servo__4__1">
  <inertial>
    <origin rpy="0 0 0" xyz="0.015363533740432825 3.599470012234868e-05 0.01352566905944469"/>
    <mass value="0.32411536495008075"/>
    <inertia ixx="7.9e-05" ixy="0.0" ixz="2e-06" iyy="9.1e-05" iyz="-0.0" izz="5e-05"/>
  </inertial>
  <visual>
    <origin rpy="0 0 0" xyz="-0.025942 0.002022 -0.354577"/>
    <geometry>
      <mesh filename="package://mvp_arm_6dof_v2_description/meshes/Servo__4__1.stl" scale="0.001 0.001 0.001"/>
    </geometry>
    <material name="silver"/>
  </visual>
  <collision>
    <origin rpy="0 0 0" xyz="-0.025942 0.002022 -0.354577"/>
    <geometry>
      <mesh filename="package://mvp_arm_6dof_v2_description/meshes/Servo__4__1.stl" scale="0.001 0.001 0.001"/>
    </geometry>
  </collision>
</link>

<link name="Bracket__3__1">
  <inertial>
    <origin rpy="0 0 0" xyz="0.01589864118251931 -0.007987181894295325 0.004097782701024066"/>
    <mass value="0.0016262220015435807"/>
    <inertia ixx="0.0" ixy="-0.0" ixz="-0.0" iyy="0.0" iyz="0.0" izz="0.0"/>
  </inertial>
  <visual>
    <origin rpy="0 0 0" xyz="-0.025243 -0.006064 -0.390552"/>
    <geometry>
      <mesh filename="package://mvp_arm_6dof_v2_description/meshes/Bracket__3__1.stl" scale="0.001 0.001 0.001"/>
    </geometry>
    <material name="silver"/>
  </visual>
  <collision>
    <origin rpy="0 0 0" xyz="-0.025243 -0.006064 -0.390552"/>
    <geometry>
      <mesh filename="package://mvp_arm_6dof_v2_description/meshes/Bracket__3__1.stl" scale="0.001 0.001 0.001"/>
    </geometry>
  </collision>
</link>

<link name="Servo_Rotator__4__1">
  <inertial>
    <origin rpy="0 0 0" xyz="0.0020392727454433754 1.9599116875569037e-05 0.008056069500829488"/>
    <mass value="0.012286224598738087"/>
    <inertia ixx="1e-06" ixy="0.0" ixz="0.0" iyy="0.0" iyz="0.0" izz="0.0"/>
  </inertial>
  <visual>
    <origin rpy="0 0 0" xyz="-0.021654 0.002042 -0.346462"/>
    <geometry>
      <mesh filename="package://mvp_arm_6dof_v2_description/meshes/Servo_Rotator__4__1.stl" scale="0.001 0.001 0.001"/>
    </geometry>
    <material name="silver"/>
  </visual>
  <collision>
    <origin rpy="0 0 0" xyz="-0.021654 0.002042 -0.346462"/>
    <geometry>
      <mesh filename="package://mvp_arm_6dof_v2_description/meshes/Servo_Rotator__4__1.stl" scale="0.001 0.001 0.001"/>
    </geometry>
  </collision>
</link>

<link name="Servo__5__1">
  <inertial>
    <origin rpy="0 0 0" xyz="0.013114397820069863 -0.015711494309324826 0.0003817734354029101"/>
    <mass value="0.32411536495008075"/>
    <inertia ixx="5e-05" ixy="-2e-06" ixz="-1e-06" iyy="7.9e-05" iyz="-0.0" izz="9.1e-05"/>
  </inertial>
  <visual>
    <origin rpy="0 0 0" xyz="0.020045 -0.01416 -0.353328"/>
    <geometry>
      <mesh filename="package://mvp_arm_6dof_v2_description/meshes/Servo__5__1.stl" scale="0.001 0.001 0.001"/>
    </geometry>
    <material name="silver"/>
  </visual>
  <collision>
    <origin rpy="0 0 0" xyz="0.020045 -0.01416 -0.353328"/>
    <geometry>
      <mesh filename="package://mvp_arm_6dof_v2_description/meshes/Servo__5__1.stl" scale="0.001 0.001 0.001"/>
    </geometry>
  </collision>
</link>

<link name="Bracket__5__1">
  <inertial>
    <origin rpy="0 0 0" xyz="0.00344356718978997 0.01601961665031654 0.008055349340560902"/>
    <mass value="0.0016262220015435807"/>
    <inertia ixx="0.0" ixy="0.0" ixz="0.0" iyy="0.0" iyz="0.0" izz="0.0"/>
  </inertial>
  <visual>
    <origin rpy="0 0 0" xyz="-0.016159 0.018043 -0.346355"/>
    <geometry>
      <mesh filename="package://mvp_arm_6dof_v2_description/meshes/Bracket__5__1.stl" scale="0.001 0.001 0.001"/>
    </geometry>
    <material name="silver"/>
  </visual>
  <collision>
    <origin rpy="0 0 0" xyz="-0.016159 0.018043 -0.346355"/>
    <geometry>
      <mesh filename="package://mvp_arm_6dof_v2_description/meshes/Bracket__5__1.stl" scale="0.001 0.001 0.001"/>
    </geometry>
  </collision>
</link>

<link name="Forearm_1">
  <inertial>
    <origin rpy="0 0 0" xyz="0.04811303961108866 1.1598853245149265e-05 0.0012336044389075207"/>
    <mass value="0.7719250888938243"/>
    <inertia ixx="0.000141" ixy="-0.0" ixz="-1.8e-05" iyy="0.000726" iyz="0.0" izz="0.000771"/>
  </inertial>
  <visual>
    <origin rpy="0 0 0" xyz="-0.073332 0.001934 -0.387836"/>
    <geometry>
      <mesh filename="package://mvp_arm_6dof_v2_description/meshes/Forearm_1.stl" scale="0.001 0.001 0.001"/>
    </geometry>
    <material name="silver"/>
  </visual>
  <collision>
    <origin rpy="0 0 0" xyz="-0.073332 0.001934 -0.387836"/>
    <geometry>
      <mesh filename="package://mvp_arm_6dof_v2_description/meshes/Forearm_1.stl" scale="0.001 0.001 0.001"/>
    </geometry>
  </collision>
</link>

<link name="Forearm_Joint_1">
  <inertial>
    <origin rpy="0 0 0" xyz="0.019749225031501748 -1.369065446798763e-05 -0.007300482312114054"/>
    <mass value="0.24639014270019174"/>
    <inertia ixx="6e-05" ixy="0.0" ixz="7e-06" iyy="9.9e-05" iyz="0.0" izz="0.000118"/>
  </inertial>
  <visual>
    <origin rpy="0 0 0" xyz="-0.033096 0.001921 -0.39628"/>
    <geometry>
      <mesh filename="package://mvp_arm_6dof_v2_description/meshes/Forearm_Joint_1.stl" scale="0.001 0.001 0.001"/>
    </geometry>
    <material name="silver"/>
  </visual>
  <collision>
    <origin rpy="0 0 0" xyz="-0.033096 0.001921 -0.39628"/>
    <geometry>
      <mesh filename="package://mvp_arm_6dof_v2_description/meshes/Forearm_Joint_1.stl" scale="0.001 0.001 0.001"/>
    </geometry>
  </collision>
</link>

<link name="Servo_Rotator__5__1">
  <inertial>
    <origin rpy="0 0 0" xyz="0.00799743271970977 -0.002248929390793089 0.00021621004086314066"/>
    <mass value="0.012286224598738087"/>
    <inertia ixx="0.0" ixy="-0.0" ixz="0.0" iyy="1e-06" iyz="-0.0" izz="0.0"/>
  </inertial>
  <visual>
    <origin rpy="0 0 0" xyz="0.028043 -0.018658 -0.353106"/>
    <geometry>
      <mesh filename="package://mvp_arm_6dof_v2_description/meshes/Servo_Rotator__5__1.stl" scale="0.001 0.001 0.001"/>
    </geometry>
    <material name="silver"/>
  </visual>
  <collision>
    <origin rpy="0 0 0" xyz="0.028043 -0.018658 -0.353106"/>
    <geometry>
      <mesh filename="package://mvp_arm_6dof_v2_description/meshes/Servo_Rotator__5__1.stl" scale="0.001 0.001 0.001"/>
    </geometry>
  </collision>
</link>

<link name="Elbow_Hinge__1__2">
  <inertial>
    <origin rpy="0 0 0" xyz="-0.013766752878679976 2.1515676582339795e-05 0.009886535758384607"/>
    <mass value="0.0037556666472927302"/>
    <inertia ixx="2e-06" ixy="0.0" ixz="0.0" iyy="1e-06" iyz="0.0" izz="1e-06"/>
  </inertial>
  <visual>
    <origin rpy="0 0 0" xyz="0.005849 0.0024 -0.327232"/>
    <geometry>
      <mesh filename="package://mvp_arm_6dof_v2_description/meshes/Elbow_Hinge__1__2.stl" scale="0.001 0.001 0.001"/>
    </geometry>
    <material name="silver"/>
  </visual>
  <collision>
    <origin rpy="0 0 0" xyz="0.005849 0.0024 -0.327232"/>
    <geometry>
      <mesh filename="package://mvp_arm_6dof_v2_description/meshes/Elbow_Hinge__1__2.stl" scale="0.001 0.001 0.001"/>
    </geometry>
  </collision>
</link>

<link name="Arm_Link_1">
  <inertial>
    <origin rpy="0 0 0" xyz="-0.002023573058774996 -0.01881587365277383 0.07708599083440679"/>
    <mass value="0.21427857804003209"/>
    <inertia ixx="0.00058" ixy="0.0" ixz="1.4e-05" iyy="0.000565" iyz="-1e-06" izz="3.7e-05"/>
  </inertial>
  <visual>
    <origin rpy="0 0 0" xyz="0.014005 -0.016203 -0.161915"/>
    <geometry>
      <mesh filename="package://mvp_arm_6dof_v2_description/meshes/Arm_Link_1.stl" scale="0.001 0.001 0.001"/>
    </geometry>
    <material name="silver"/>
  </visual>
  <collision>
    <origin rpy="0 0 0" xyz="0.014005 -0.016203 -0.161915"/>
    <geometry>
      <mesh filename="package://mvp_arm_6dof_v2_description/meshes/Arm_Link_1.stl" scale="0.001 0.001 0.001"/>
    </geometry>
  </collision>
</link>

<link name="Shoulder_Joint_1">
  <inertial>
    <origin rpy="0 0 0" xyz="-0.0002783520807599555 0.001716966723272633 0.013009417733686551"/>
    <mass value="0.1980303324276481"/>
    <inertia ixx="0.00026" ixy="-0.0" ixz="-5e-06" iyy="0.000259" iyz="-5e-06" izz="0.00042"/>
  </inertial>
  <visual>
    <origin rpy="0 0 0" xyz="0.001172 0.00337 -0.130745"/>
    <geometry>
      <mesh filename="package://mvp_arm_6dof_v2_description/meshes/Shoulder_Joint_1.stl" scale="0.001 0.001 0.001"/>
    </geometry>
    <material name="silver"/>
  </visual>
  <collision>
    <origin rpy="0 0 0" xyz="0.001172 0.00337 -0.130745"/>
    <geometry>
      <mesh filename="package://mvp_arm_6dof_v2_description/meshes/Shoulder_Joint_1.stl" scale="0.001 0.001 0.001"/>
    </geometry>
  </collision>
</link>

<link name="Wrist_Hinge_1">
  <inertial>
    <origin rpy="0 0 0" xyz="0.0001687834064507121 0.020961349127553694 -0.008348654777393216"/>
    <mass value="0.0037556666472927302"/>
    <inertia ixx="2e-06" ixy="0.0" ixz="0.0" iyy="1e-06" iyz="0.0" izz="1e-06"/>
  </inertial>
  <visual>
    <origin rpy="0 0 0" xyz="-0.214953 0.022686 -0.383658"/>
    <geometry>
      <mesh filename="package://mvp_arm_6dof_v2_description/meshes/Wrist_Hinge_1.stl" scale="0.001 0.001 0.001"/>
    </geometry>
    <material name="silver"/>
  </visual>
  <collision>
    <origin rpy="0 0 0" xyz="-0.214953 0.022686 -0.383658"/>
    <geometry>
      <mesh filename="package://mvp_arm_6dof_v2_description/meshes/Wrist_Hinge_1.stl" scale="0.001 0.001 0.001"/>
    </geometry>
  </collision>
</link>

<link name="Bracket__1__1">
  <inertial>
    <origin rpy="0 0 0" xyz="0.0016732761117350947 -9.794040194281229e-05 0.008036379638807933"/>
    <mass value="0.0016262220015435807"/>
    <inertia ixx="0.0" ixy="-0.0" ixz="0.0" iyy="0.0" iyz="0.0" izz="0.0"/>
  </inertial>
  <visual>
    <origin rpy="0 0 0" xyz="-0.237016 0.002383 -0.316012"/>
    <geometry>
      <mesh filename="package://mvp_arm_6dof_v2_description/meshes/Bracket__1__1.stl" scale="0.001 0.001 0.001"/>
    </geometry>
    <material name="silver"/>
  </visual>
  <collision>
    <origin rpy="0 0 0" xyz="-0.237016 0.002383 -0.316012"/>
    <geometry>
      <mesh filename="package://mvp_arm_6dof_v2_description/meshes/Bracket__1__1.stl" scale="0.001 0.001 0.001"/>
    </geometry>
  </collision>
</link>

<link name="Servo__1__1">
  <inertial>
    <origin rpy="0 0 0" xyz="0.023226772127093703 -0.007790584361720188 -0.016092423843160952"/>
    <mass value="0.32411536495008075"/>
    <inertia ixx="5e-05" ixy="0.0" ixz="-2e-06" iyy="9.1e-05" iyz="0.0" izz="7.9e-05"/>
  </inertial>
  <visual>
    <origin rpy="0 0 0" xyz="-0.242009 -0.005322 -0.340218"/>
    <geometry>
      <mesh filename="package://mvp_arm_6dof_v2_description/meshes/Servo__1__1.stl" scale="0.001 0.001 0.001"/>
    </geometry>
    <material name="silver"/>
  </visual>
  <collision>
    <origin rpy="0 0 0" xyz="-0.242009 -0.005322 -0.340218"/>
    <geometry>
      <mesh filename="package://mvp_arm_6dof_v2_description/meshes/Servo__1__1.stl" scale="0.001 0.001 0.001"/>
    </geometry>
  </collision>
</link>

<link name="Bracket__4__1">
  <inertial>
    <origin rpy="0 0 0" xyz="-0.007959256120512181 -1.0287947060996566e-05 -0.002008019445163489"/>
    <mass value="0.0016262220015435807"/>
    <inertia ixx="0.0" ixy="-0.0" ixz="-0.0" iyy="0.0" iyz="0.0" izz="0.0"/>
  </inertial>
  <visual>
    <origin rpy="0 0 0" xyz="-0.223335 0.00177 -0.365233"/>
    <geometry>
      <mesh filename="package://mvp_arm_6dof_v2_description/meshes/Bracket__4__1.stl" scale="0.001 0.001 0.001"/>
    </geometry>
    <material name="silver"/>
  </visual>
  <collision>
    <origin rpy="0 0 0" xyz="-0.223335 0.00177 -0.365233"/>
    <geometry>
      <mesh filename="package://mvp_arm_6dof_v2_description/meshes/Bracket__4__1.stl" scale="0.001 0.001 0.001"/>
    </geometry>
  </collision>
</link>

<link name="Bracket__2__1">
  <inertial>
    <origin rpy="0 0 0" xyz="0.0021702523840013976 -5.735108448202508e-05 -0.012446942249239479"/>
    <mass value="0.0016262220015435807"/>
    <inertia ixx="0.0" ixy="0.0" ixz="0.0" iyy="0.0" iyz="0.0" izz="0.0"/>
  </inertial>
  <visual>
    <origin rpy="0 0 0" xyz="-0.172968 0.001852 -0.402964"/>
    <geometry>
      <mesh filename="package://mvp_arm_6dof_v2_description/meshes/Bracket__2__1.stl" scale="0.001 0.001 0.001"/>
    </geometry>
    <material name="silver"/>
  </visual>
  <collision>
    <origin rpy="0 0 0" xyz="-0.172968 0.001852 -0.402964"/>
    <geometry>
      <mesh filename="package://mvp_arm_6dof_v2_description/meshes/Bracket__2__1.stl" scale="0.001 0.001 0.001"/>
    </geometry>
  </collision>
</link>

<link name="Gripper_Slider_1">
  <inertial>
    <origin rpy="0 0 0" xyz="0.029607737023973846 0.013304628840371863 -0.0014577479840566787"/>
    <mass value="0.006653616089325752"/>
    <inertia ixx="3e-06" ixy="0.0" ixz="-0.0" iyy="2e-06" iyz="-0.0" izz="5e-06"/>
  </inertial>
  <visual>
    <origin rpy="0 0 0" xyz="-0.247936 0.015781 -0.30813"/>
    <geometry>
      <mesh filename="package://mvp_arm_6dof_v2_description/meshes/Gripper_Slider_1.stl" scale="0.001 0.001 0.001"/>
    </geometry>
    <material name="silver"/>
  </visual>
  <collision>
    <origin rpy="0 0 0" xyz="-0.247936 0.015781 -0.30813"/>
    <geometry>
      <mesh filename="package://mvp_arm_6dof_v2_description/meshes/Gripper_Slider_1.stl" scale="0.001 0.001 0.001"/>
    </geometry>
  </collision>
</link>

<!-- <link name="Left_Servo_Finger_Connector_1">
  <inertial>
    <origin rpy="0 0 0" xyz="0.0001409165693066483 0.010442814922828104 -0.0009679780292277673"/>
    <mass value="0.0017321558106604333"/>
    <inertia ixx="0.0" ixy="-0.0" ixz="-0.0" iyy="0.0" iyz="-0.0" izz="0.0"/>
  </inertial>
  <visual>
    <origin rpy="0 0 0" xyz="-0.278517 -0.005779 -0.304252"/>
    <geometry>
      <mesh filename="package://mvp_arm_6dof_v2_description/meshes/Left_Servo_Finger_Connector_1.stl" scale="0.001 0.001 0.001"/>
    </geometry>
    <material name="silver"/>
  </visual>
  <collision>
    <origin rpy="0 0 0" xyz="-0.278517 -0.005779 -0.304252"/>
    <geometry>
      <mesh filename="package://mvp_arm_6dof_v2_description/meshes/Left_Servo_Finger_Connector_1.stl" scale="0.001 0.001 0.001"/>
    </geometry>
  </collision>
</link>

<link name="Right_Servo_Finger_Connector_1">
  <inertial>
    <origin rpy="0 0 0" xyz="-0.00010094571347429859 -0.010400537016847079 -0.0012314094427017253"/>
    <mass value="0.0017321558106604333"/>
    <inertia ixx="0.0" ixy="0.0" ixz="-0.0" iyy="0.0" iyz="-0.0" izz="0.0"/>
  </inertial>
  <visual>
    <origin rpy="0 0 0" xyz="-0.279028 0.010212 -0.304066"/>
    <geometry>
      <mesh filename="package://mvp_arm_6dof_v2_description/meshes/Right_Servo_Finger_Connector_1.stl" scale="0.001 0.001 0.001"/>
    </geometry>
    <material name="silver"/>
  </visual>
  <collision>
    <origin rpy="0 0 0" xyz="-0.279028 0.010212 -0.304066"/>
    <geometry>
      <mesh filename="package://mvp_arm_6dof_v2_description/meshes/Right_Servo_Finger_Connector_1.stl" scale="0.001 0.001 0.001"/>
    </geometry>
  </collision>
</link> -->

<link name="Right_Gripper_Finger_1">
  <inertial>
    <origin rpy="0 0 0" xyz="-0.019770206172384563 0.013486368095181816 -0.01214469345139918"/>
    <mass value="0.00839361387509603"/>
    <inertia ixx="1e-06" ixy="-0.0" ixz="-0.0" iyy="2e-06" iyz="0.0" izz="1e-06"/>
  </inertial>
  <visual>
    <origin rpy="0 0 0" xyz="-0.299019 0.03819 -0.30253"/>
    <geometry>
      <mesh filename="package://mvp_arm_6dof_v2_description/meshes/Right_Gripper_Finger_1.stl" scale="0.001 0.001 0.001"/>
    </geometry>
    <material name="silver"/>
  </visual>
  <collision>
    <origin rpy="0 0 0" xyz="-0.299019 0.03819 -0.30253"/>
    <geometry>
      <mesh filename="package://mvp_arm_6dof_v2_description/meshes/Right_Gripper_Finger_1.stl" scale="0.001 0.001 0.001"/>
    </geometry>
  </collision>
</link>

<link name="Left_Gripper_Finger_1">
  <inertial>
    <origin rpy="0 0 0" xyz="0.00023833865276129407 -0.00604606763680195 -0.0113424483965332"/>
    <mass value="0.008393613874943608"/>
    <inertia ixx="1e-06" ixy="0.0" ixz="-0.0" iyy="2e-06" iyz="-0.0" izz="1e-06"/>
  </inertial>
  <visual>
    <origin rpy="0 0 0" xyz="-0.278989 -0.026646 -0.302287"/>
    <geometry>
      <mesh filename="package://mvp_arm_6dof_v2_description/meshes/Left_Gripper_Finger_1.stl" scale="0.001 0.001 0.001"/>
    </geometry>
    <material name="silver"/>
  </visual>
  <collision>
    <origin rpy="0 0 0" xyz="-0.278989 -0.026646 -0.302287"/>
    <geometry>
      <mesh filename="package://mvp_arm_6dof_v2_description/meshes/Left_Gripper_Finger_1.stl" scale="0.001 0.001 0.001"/>
    </geometry>
  </collision>
</link>

<joint name="Rev7" type="continuous">
  <origin rpy="0 0 0" xyz="0.036669 -0.007594 -0.031528"/>
  <parent link="Servo__1__1"/>
  <child link="Servo_Rotator__1__1"/>
  <axis xyz="0.020917 0.012351 -0.999705"/>
</joint>

<joint name="Rev6" type="continuous">
  <origin rpy="0 0 0" xyz="0.036198 -0.000278 -0.007048"/>
  <parent link="Servo__3__1"/>
  <child link="Servo_Rotator__2__1"/>
  <axis xyz="-0.000119 0.999989 -0.004607"/>
</joint>

<joint name="Rigid4" type="fixed">
  <origin rpy="0 0 0" xyz="0.005619 -0.016019 -0.00428"/>
  <parent link="Bracket__2__1"/>
  <child link="Servo__3__1"/>
</joint>

<joint name="Rigid5" type="fixed">
  <origin rpy="0 0 0" xyz="0.009479 0.00796 -0.00884"/>
  <parent link="Bracket__4__1"/>
  <child link="Servo__2__1"/>
</joint>

<joint name="Rev5" type="continuous">
  <origin rpy="0 0 0" xyz="-0.000465 -0.008672 -0.032477"/>
  <parent link="Servo__2__1"/>
  <child link="Servo_Rotator__3__1"/>
  <axis xyz="0.999781 0.000215 0.020922"/>
</joint>

<joint name="Rev4" type="continuous">
  <origin rpy="0 0 0" xyz="0.004288 2e-05 0.008115"/>
  <parent link="Servo_Rotator__4__1"/>
  <child link="Servo__4__1"/>
  <axis xyz="0.999653 0.00024 0.026324"/>
</joint>

<joint name="Rigid7" type="fixed">
  <origin rpy="0 0 0" xyz="-0.000699 0.008086 0.035975"/>
  <parent link="Servo__4__1"/>
  <child link="Bracket__3__1"/>
</joint>

<joint name="Rigid8" type="fixed">
  <origin rpy="0 0 0" xyz="0.005495 0.016001 0.000107"/>
  <parent link="Bracket__5__1"/>
  <child link="Servo_Rotator__4__1"/>
</joint>

<joint name="Rev3" type="continuous">
  <origin rpy="0 0 0" xyz="0.007998 -0.004498 0.000222"/>
  <parent link="Servo_Rotator__5__1"/>
  <child link="Servo__5__1"/>
  <axis xyz="0.000177 -0.999997 0.002395"/>
</joint>

<joint name="Rigid9" type="fixed">
  <origin rpy="0 0 0" xyz="0.036204 -0.032203 -0.006973"/>
  <parent link="Servo__5__1"/>
  <child link="Bracket__5__1"/>
</joint>

<joint name="Rigid11" type="fixed">
  <origin rpy="0 0 0" xyz="0.040236 -1.3e-05 -0.008444"/>
  <parent link="Forearm_Joint_1"/>
  <child link="Forearm_1"/>
</joint>

<joint name="Rigid13" type="fixed">
  <origin rpy="0 0 0" xyz="0.007853 -0.007985 0.005728"/>
  <parent link="Bracket__3__1"/>
  <child link="Forearm_Joint_1"/>
</joint>

<joint name="Rigid14" type="fixed">
  <origin rpy="0 0 0" xyz="-0.022194 0.021058 0.025874"/>
  <parent link="Elbow_Hinge__1__2"/>
  <child link="Servo_Rotator__5__1"/>
</joint>

<joint name="Rigid15" type="fixed">
  <origin rpy="0 0 0" xyz="0.008156 -0.018603 0.165317"/>
  <parent link="Arm_Link_1"/>
  <child link="Elbow_Hinge__1__2"/>
</joint>

<joint name="Rev2" type="continuous">
  <origin rpy="0 0 0" xyz="-0.012833 0.019573 0.03117"/>
  <parent link="Shoulder_Joint_1"/>
  <child link="Arm_Link_1"/>
  <axis xyz="-0.000177 0.999997 -0.002395"/>
</joint>

<joint name="Rev1" type="continuous">
  <origin rpy="0 0 0" xyz="-0.001172 -0.00337 0.130745"/>
  <parent link="base_link"/>
  <child link="Shoulder_Joint_1"/>
  <axis xyz="0.026933 -0.00239 -0.999634"/>
</joint>

<joint name="Rigid16" type="fixed">
  <origin rpy="0 0 0" xyz="0.000168 -0.004537 -0.007978"/>
  <parent link="Servo_Rotator__2__1"/>
  <child link="Wrist_Hinge_1"/>
</joint>

<joint name="Rigid70" type="fixed">
  <origin rpy="0 0 0" xyz="0.004667 9.9e-05 -0.007904"/>
  <parent link="Servo_Rotator__3__1"/>
  <child link="Bracket__1__1"/>
</joint>

<joint name="Rigid71" type="fixed">
  <origin rpy="0 0 0" xyz="0.004993 0.007705 0.024206"/>
  <parent link="Bracket__1__1"/>
  <child link="Servo__1__1"/>
</joint>

<joint name="Rigid72" type="fixed">
  <origin rpy="0 0 0" xyz="0.008382 0.020916 -0.018425"/>
  <parent link="Wrist_Hinge_1"/>
  <child link="Bracket__4__1"/>
</joint>

<joint name="Rigid74" type="fixed">
  <origin rpy="0 0 0" xyz="0.099636 8.2e-05 0.015128"/>
  <parent link="Forearm_1"/>
  <child link="Bracket__2__1"/>
</joint>

<joint name="Rigid85" type="fixed">
  <origin rpy="0 0 0" xyz="0.005927 -0.021103 -0.032088"/>
  <parent link="Servo__1__1"/>
  <child link="Gripper_Slider_1"/>
</joint>

<!-- <joint name="Rev8" type="continuous">
  <origin rpy="0 0 0" xyz="-0.000161 0.008051 -0.004438"/>
  <parent link="Servo_Rotator__1__1"/>
  <child link="Left_Servo_Finger_Connector_1"/>
  <axis xyz="0.020917 0.012351 -0.999705"/>
</joint>

<joint name="Rev9" type="continuous">
  <origin rpy="0 0 0" xyz="0.00035 -0.00794 -0.004624"/>
  <parent link="Servo_Rotator__1__1"/>
  <child link="Right_Servo_Finger_Connector_1"/>
  <axis xyz="0.020917 0.012351 -0.999705"/>
</joint>

<joint name="Rev10" type="continuous">
  <origin rpy="0 0 0" xyz="0.019991 -0.027978 -0.001536"/>
  <parent link="Right_Servo_Finger_Connector_1"/>
  <child link="Right_Gripper_Finger_1"/>
  <axis xyz="0.020917 0.012351 -0.999705"/>
</joint>

<joint name="Rev11" type="continuous">
  <origin rpy="0 0 0" xyz="0.000472 0.020867 -0.001965"/>
  <parent link="Left_Servo_Finger_Connector_1"/>
  <child link="Left_Gripper_Finger_1"/>
  <axis xyz="0.020917 0.012351 -0.999705"/>
</joint> -->

<joint name="Slider1" type="prismatic">
  <origin rpy="0 0 0" xyz="0.051083 -0.022409 -0.0056"/>
  <parent link="Gripper_Slider_1"/>
  <child link="Right_Gripper_Finger_1"/>
  <axis xyz="-0.000474 0.999924 0.012343"/>
  <limit effort="100" lower="0.0" upper=".0150" velocity="100"/>
</joint>

<joint name="Slider2" type="prismatic">
  <origin rpy="0 0 0" xyz="0.031053 0.042427 -0.005843"/>
  <parent link="Gripper_Slider_1"/>
  <child link="Left_Gripper_Finger_1"/>
  <axis xyz="-0.000474 0.999924 0.012343"/>
  <limit effort="100" lower="-.0150" upper="0" velocity="100"/>
</joint>
</robot>
