<?xml version="1.0" ?>
<robot name="protoarm" xmlns:xacro="http://www.ros.org/wiki/xacro">

<xacro:include filename="$(find protoarm_description)/urdf/materials.xacro" />
<xacro:include filename="$(find protoarm_description)/urdf/protoarm.trans" />
<xacro:include filename="$(find protoarm_description)/urdf/protoarm.gazebo" />
<link name="world"/>
<link name="base_link">
  <inertial>
    <origin xyz="0 0 0" rpy="0 0 0" />
    <mass value="3.06" />
    <inertia ixx="0.3" ixy="0.0" ixz="0.0" iyy="0.3" iyz="0.0" izz="0.3" />
	</inertial>
  <visual>
    <origin rpy="0 0 0" xyz="0 0 0"/>
    <geometry>
      <mesh filename="package://protoarm_description/meshes/base_link.stl" scale="0.001 0.001 0.001"/>
    </geometry>
    <material name="silver"/>
  </visual>
  <collision>
    <origin rpy="0 0 0" xyz="0 0 0"/>
    <geometry>
      <mesh filename="package://protoarm_description/meshes/base_link.stl" scale="0.001 0.001 0.001"/>
    </geometry>
  </collision>
</link>

<link name="link_1_v1_1">
  <inertial>
    <origin xyz="0 0 0" rpy="0 0 0" />
    <mass value="3.06" />
    <inertia ixx="0.3" ixy="0.0" ixz="0.0" iyy="0.3" iyz="0.0" izz="0.3" />
	</inertial>
  <visual>
    <origin rpy="0 0 0" xyz="0.006279 -0.004346 -0.131179"/>
    <geometry>
      <mesh filename="package://protoarm_description/meshes/link_1_v1_1.stl" scale="0.001 0.001 0.001"/>
    </geometry>
    <material name="silver"/>
  </visual>
  <collision>
    <origin rpy="0 0 0" xyz="0.006279 -0.004346 -0.131179"/>
    <geometry>
      <mesh filename="package://protoarm_description/meshes/link_1_v1_1.stl" scale="0.001 0.001 0.001"/>
    </geometry>
  </collision>
</link>

<link name="link_2_v1_1">
  <inertial>
    <origin xyz="0 0 0" rpy="0 0 0" />
    <mass value="3.06" />
    <inertia ixx="0.3" ixy="0.0" ixz="0.0" iyy="0.3" iyz="0.0" izz="0.3" />
	</inertial>
  <visual>
    <origin rpy="0 0 0" xyz="0.020207 -0.000222 -0.17144"/>
    <geometry>
      <mesh filename="package://protoarm_description/meshes/link_2_v1_1.stl" scale="0.001 0.001 0.001"/>
    </geometry>
    <material name="silver"/>
  </visual>
  <collision>
    <origin rpy="0 0 0" xyz="0.020207 -0.000222 -0.17144"/>
    <geometry>
      <mesh filename="package://protoarm_description/meshes/link_2_v1_1.stl" scale="0.001 0.001 0.001"/>
    </geometry>
  </collision>
</link>

<link name="gear2_v1_1">
  <inertial>
    <origin xyz="0 0 0" rpy="0 0 0" />
    <mass value="0.1" />
    <inertia ixx="0.1" ixy="0.0" ixz="0.0" iyy="0.1" iyz="0.0" izz="0.1" />
	</inertial>
  <visual>
    <origin rpy="0 0 0" xyz="0.174125 0.013949 -0.306984"/>
    <geometry>
      <mesh filename="package://protoarm_description/meshes/gear2_v1_1.stl" scale="0.001 0.001 0.001"/>
    </geometry>
    <material name="silver"/>
  </visual>
  <collision>
    <origin rpy="0 0 0" xyz="0.174125 0.013949 -0.306984"/>
    <geometry>
      <mesh filename="package://protoarm_description/meshes/gear2_v1_1.stl" scale="0.001 0.001 0.001"/>
    </geometry>
  </collision>
</link>

<link name="gear1_v1_1">
  <inertial>
    <origin xyz="0 0 0" rpy="0 0 0" />
    <mass value="0.1" />
    <inertia ixx="0.1" ixy="0.0" ixz="0.0" iyy="0.1" iyz="0.0" izz="0.1" />
	</inertial>
  <visual>
    <origin rpy="0 0 0" xyz="0.174859 -0.012922 -0.30596"/>
    <geometry>
      <mesh filename="package://protoarm_description/meshes/gear1_v1_1.stl" scale="0.001 0.001 0.001"/>
    </geometry>
    <material name="silver"/>
  </visual>
  <collision>
    <origin rpy="0 0 0" xyz="0.174859 -0.012922 -0.30596"/>
    <geometry>
      <mesh filename="package://protoarm_description/meshes/gear1_v1_1.stl" scale="0.001 0.001 0.001"/>
    </geometry>
  </collision>
</link>

<link name="gripper_base_v1_1">
  <inertial>
    <origin xyz="0 0 0" rpy="0 0 0" />
    <mass value="3.06" />
    <inertia ixx="0.3" ixy="0.0" ixz="0.0" iyy="0.3" iyz="0.0" izz="0.3" />
	</inertial>
  <visual>
    <origin rpy="0 0 0" xyz="0.135027 -0.00469 -0.297799"/>
    <geometry>
      <mesh filename="package://protoarm_description/meshes/gripper_base_v1_1.stl" scale="0.001 0.001 0.001"/>
    </geometry>
    <material name="silver"/>
  </visual>
  <collision>
    <origin rpy="0 0 0" xyz="0.135027 -0.00469 -0.297799"/>
    <geometry>
      <mesh filename="package://protoarm_description/meshes/gripper_base_v1_1.stl" scale="0.001 0.001 0.001"/>
    </geometry>
  </collision>
</link>

<link name="link_4_v1_1">
  <inertial>
    <origin xyz="0 0 0" rpy="0 0 0" />
    <mass value="3.06" />
    <inertia ixx="0.3" ixy="0.0" ixz="0.0" iyy="0.3" iyz="0.0" izz="0.3" />
	</inertial>
  <visual>
    <origin rpy="0 0 0" xyz="0.107006 0.008795 -0.291635"/>
    <geometry>
      <mesh filename="package://protoarm_description/meshes/link_4_v1_1.stl" scale="0.001 0.001 0.001"/>
    </geometry>
    <material name="silver"/>
  </visual>
  <collision>
    <origin rpy="0 0 0" xyz="0.107006 0.008795 -0.291635"/>
    <geometry>
      <mesh filename="package://protoarm_description/meshes/link_4_v1_1.stl" scale="0.001 0.001 0.001"/>
    </geometry>
  </collision>
</link>

<link name="link_3_v1_1">
  <inertial>
    <origin xyz="0 0 0" rpy="0 0 0" />
    <mass value="3.06" />
    <inertia ixx="0.3" ixy="0.0" ixz="0.0" iyy="0.3" iyz="0.0" izz="0.3" />
	</inertial>
  <visual>
    <origin rpy="0 0 0" xyz="0.017319 -0.000979 -0.291403"/>
    <geometry>
      <mesh filename="package://protoarm_description/meshes/link_3_v1_1.stl" scale="0.001 0.001 0.001"/>
    </geometry>
    <material name="silver"/>
  </visual>
  <collision>
    <origin rpy="0 0 0" xyz="0.017319 -0.000979 -0.291403"/>
    <geometry>
      <mesh filename="package://protoarm_description/meshes/link_3_v1_1.stl" scale="0.001 0.001 0.001"/>
    </geometry>
  </collision>
</link>

<joint name="grouding" type="fixed">
	<parent link="world"/>
	<child link="base_link"/>
</joint>

<joint name="Rev1" type="continuous">
  <origin rpy="0 0 0" xyz="-0.006279 0.004346 0.131179"/>
  <parent link="base_link"/>
  <child link="link_1_v1_1"/>
	<limit effort="30" velocity="1.0" lower="-1.57" upper="1.57" />
  <axis xyz="-0.002854 0.005633 0.99998"/>
</joint>

<joint name="Rev2" type="continuous">
  <origin rpy="0 0 0" xyz="-0.013928 -0.004124 0.040261"/>
  <parent link="link_1_v1_1"/>
  <child link="link_2_v1_1"/>
	<limit effort="30" velocity="1.0" lower="-1.57" upper="1.57" />
  <axis xyz="-0.025335 0.999663 -0.005703"/>

</joint>

<joint name="Rev5" type="continuous">
  <origin rpy="0 0 0" xyz="-0.039098 -0.018639 0.009185"/>
  <parent link="gripper_base_v1_1"/>
  <child link="gear2_v1_1"/>
	<limit effort="30" velocity="1.0" lower="-1.57" upper="1.57" />
  <axis xyz="-0.141793 0.033815 0.989319"/>

</joint>

<joint name="Rev6" type="continuous">
  <origin rpy="0 0 0" xyz="-0.039832 0.008232 0.008161"/>
  <parent link="gripper_base_v1_1"/>
  <child link="gear1_v1_1"/>
	<limit effort="30" velocity="1.0" lower="-1.57" upper="1.57" />
  <axis xyz="-0.141793 0.033815 0.989319"/>

</joint>


<joint name="Rev4" type="continuous">
  <origin rpy="0 0 0" xyz="-0.028021 0.013485 0.006164"/>
  <parent link="link_4_v1_1"/>
  <child link="gripper_base_v1_1"/>
	<limit effort="30" velocity="1.0" lower="-1.57" upper="1.57" />
  <axis xyz="0.027296 -0.998903 0.038055"/>

</joint>

<joint name="Rigid1" type="fixed">
  <origin rpy="0 0 0" xyz="-0.089687 -0.009774 0.000232"/>
  <parent link="link_3_v1_1"/>
  <child link="link_4_v1_1"/>
</joint>

<joint name="Rev3" type="continuous">
  <origin rpy="0 0 0" xyz="0.002888 0.000757 0.119963"/>
  <parent link="link_2_v1_1"/>
  <child link="link_3_v1_1"/>
	<limit effort="30" velocity="1.0" lower="-0.79" upper="0.79" />
  <axis xyz="0.025335 -0.999663 0.005703"/>

</joint>

</robot>
