<?xml version="1.0" ?>
<!-- =================================================================================== -->
<!-- |    This document was autogenerated by xacro from protoarm.xacro                 | -->
<!-- |    EDITING THIS FILE BY HAND IS NOT RECOMMENDED                                 | -->
<!-- =================================================================================== -->
<robot name="protoarm">
  <material name="silver_default">
    <color rgba="0.700 0.700 0.700 1.000"/>
  </material>
  <transmission name="Rev1_tran">
    <type>transmission_interface/SimpleTransmission</type>
    <joint name="Rev1">
      <hardwareInterface>hardware_interface/EffortJointInterface</hardwareInterface>
    </joint>
    <actuator name="Rev1_actr">
      <hardwareInterface>hardware_interface/EffortJointInterface</hardwareInterface>
      <mechanicalReduction>1</mechanicalReduction>
    </actuator>
  </transmission>
  <transmission name="Rev2_tran">
    <type>transmission_interface/SimpleTransmission</type>
    <joint name="Rev2">
      <hardwareInterface>hardware_interface/EffortJointInterface</hardwareInterface>
    </joint>
    <actuator name="Rev2_actr">
      <hardwareInterface>hardware_interface/EffortJointInterface</hardwareInterface>
      <mechanicalReduction>1</mechanicalReduction>
    </actuator>
  </transmission>
  <transmission name="Rev3_tran">
    <type>transmission_interface/SimpleTransmission</type>
    <joint name="Rev3">
      <hardwareInterface>hardware_interface/EffortJointInterface</hardwareInterface>
    </joint>
    <actuator name="Rev3_actr">
      <hardwareInterface>hardware_interface/EffortJointInterface</hardwareInterface>
      <mechanicalReduction>1</mechanicalReduction>
    </actuator>
  </transmission>
  <transmission name="Rev4_tran">
    <type>transmission_interface/SimpleTransmission</type>
    <joint name="Rev4">
      <hardwareInterface>hardware_interface/EffortJointInterface</hardwareInterface>
    </joint>
    <actuator name="Rev4_actr">
      <hardwareInterface>hardware_interface/EffortJointInterface</hardwareInterface>
      <mechanicalReduction>1</mechanicalReduction>
    </actuator>
  </transmission>
  <transmission name="Rev5_tran">
    <type>transmission_interface/SimpleTransmission</type>
    <joint name="Rev5">
      <hardwareInterface>hardware_interface/EffortJointInterface</hardwareInterface>
    </joint>
    <actuator name="Rev5_actr">
      <hardwareInterface>hardware_interface/EffortJointInterface</hardwareInterface>
      <mechanicalReduction>1</mechanicalReduction>
    </actuator>
  </transmission>
  <transmission name="G_Rev2_tran">
    <type>transmission_interface/SimpleTransmission</type>
    <joint name="G_Rev2">
      <hardwareInterface>hardware_interface/EffortJointInterface</hardwareInterface>
    </joint>
    <actuator name="G_Rev2_actr">
      <hardwareInterface>hardware_interface/EffortJointInterface</hardwareInterface>
      <mechanicalReduction>1</mechanicalReduction>
    </actuator>
  </transmission>
  <transmission name="G_Rev3_tran">
    <type>transmission_interface/SimpleTransmission</type>
    <joint name="G_Rev3">
      <hardwareInterface>hardware_interface/EffortJointInterface</hardwareInterface>
    </joint>
    <actuator name="G_Rev3_actr">
      <hardwareInterface>hardware_interface/EffortJointInterface</hardwareInterface>
      <mechanicalReduction>1</mechanicalReduction>
    </actuator>
  </transmission>
  <transmission name="G_Rev1_tran">
    <type>transmission_interface/SimpleTransmission</type>
    <joint name="G_Rev1">
      <hardwareInterface>hardware_interface/EffortJointInterface</hardwareInterface>
    </joint>
    <actuator name="G_Rev1_actr">
      <hardwareInterface>hardware_interface/EffortJointInterface</hardwareInterface>
      <mechanicalReduction>1</mechanicalReduction>
    </actuator>
  </transmission>
  <transmission name="G_Rev4_tran">
    <type>transmission_interface/SimpleTransmission</type>
    <joint name="G_Rev4">
      <hardwareInterface>hardware_interface/EffortJointInterface</hardwareInterface>
    </joint>
    <actuator name="G_Rev4_actr">
      <hardwareInterface>hardware_interface/EffortJointInterface</hardwareInterface>
      <mechanicalReduction>1</mechanicalReduction>
    </actuator>
  </transmission>
  <gazebo>
    <plugin filename="libgazebo_ros_control.so" name="control"/>
  </gazebo>
  <gazebo reference="base_link">
    <material>Gazebo/Silver</material>
    <mu1>0.2</mu1>
    <mu2>0.2</mu2>
    <selfCollide>true</selfCollide>
    <gravity>true</gravity>
  </gazebo>
  <gazebo reference="shoulder_1">
    <material>Gazebo/Silver</material>
    <mu1>0.2</mu1>
    <mu2>0.2</mu2>
    <selfCollide>true</selfCollide>
  </gazebo>
  <gazebo reference="humerus_1">
    <material>Gazebo/Silver</material>
    <mu1>0.2</mu1>
    <mu2>0.2</mu2>
    <selfCollide>true</selfCollide>
  </gazebo>
  <gazebo reference="wrist_1">
    <material>Gazebo/Silver</material>
    <mu1>0.2</mu1>
    <mu2>0.2</mu2>
    <selfCollide>true</selfCollide>
  </gazebo>
  <gazebo reference="forearm_1">
    <material>Gazebo/Silver</material>
    <mu1>0.2</mu1>
    <mu2>0.2</mu2>
    <selfCollide>true</selfCollide>
  </gazebo>
  <gazebo reference="palm_1">
    <material>Gazebo/Silver</material>
    <mu1>0.2</mu1>
    <mu2>0.2</mu2>
    <selfCollide>true</selfCollide>
  </gazebo>
  <gazebo reference="right_gear_1">
    <material>Gazebo/Silver</material>
    <mu1>0.2</mu1>
    <mu2>0.2</mu2>
    <selfCollide>true</selfCollide>
  </gazebo>
  <gazebo reference="right_finger_1">
    <material>Gazebo/Silver</material>
    <mu1>0.2</mu1>
    <mu2>0.2</mu2>
    <selfCollide>true</selfCollide>
  </gazebo>
  <gazebo reference="left_gear_1">
    <material>Gazebo/Silver</material>
    <mu1>0.2</mu1>
    <mu2>0.2</mu2>
    <selfCollide>true</selfCollide>
  </gazebo>
  <gazebo reference="left_finger_1">
    <material>Gazebo/Silver</material>
    <mu1>0.2</mu1>
    <mu2>0.2</mu2>
    <selfCollide>true</selfCollide>
  </gazebo>
  <link name="world"/>
  <link name="base_link">
    <inertial>
      <origin rpy="0 0 0" xyz="-0.005977131812596751 0.0034085511625430998 0.04750670712014007"/>
      <mass value="2.456555111592732"/>
      <inertia ixx="0.00924" ixy="-9.9e-05" ixz="1.9e-05" iyy="0.009207" iyz="-5e-06" izz="0.009587"/>
    </inertial>
    <visual>
      <origin rpy="0 0 0" xyz="0 0 0"/>
      <geometry>
        <mesh filename="package://protoarm_description/meshes/base_link.stl" scale="0.001 0.001 0.001"/>
      </geometry>
      <material name="silver_default"/>
    </visual>
    <collision>
      <origin rpy="0 0 0" xyz="0 0 0"/>
      <geometry>
        <mesh filename="package://protoarm_description/meshes/base_link.stl" scale="0.001 0.001 0.001"/>
      </geometry>
    </collision>
  </link>
  <link name="shoulder_1">
    <inertial>
      <origin rpy="0 0 0" xyz="-0.0012586062575677065 -0.006369596212062548 0.017322156193060212"/>
      <mass value="0.5341010747394327"/>
      <inertia ixx="0.000353" ixy="-7e-06" ixz="4.8e-05" iyy="0.000457" iyz="4.2e-05" izz="0.000429"/>
    </inertial>
    <visual>
      <origin rpy="0 0 0" xyz="0.006279 -0.004346 -0.131179"/>
      <geometry>
        <mesh filename="package://protoarm_description/meshes/shoulder_1.stl" scale="0.001 0.001 0.001"/>
      </geometry>
      <material name="silver_default"/>
    </visual>
    <collision>
      <origin rpy="0 0 0" xyz="0.006279 -0.004346 -0.131179"/>
      <geometry>
        <mesh filename="package://protoarm_description/meshes/shoulder_1.stl" scale="0.001 0.001 0.001"/>
      </geometry>
    </collision>
  </link>
  <link name="humerus_1">
    <inertial>
      <origin rpy="0 0 0" xyz="0.0012276439170236068 0.008160238213973405 0.05914223528678397"/>
      <mass value="0.5015278384318742"/>
      <inertia ixx="0.00084" ixy="-1e-06" ixz="-1.9e-05" iyy="0.000878" iyz="-3e-06" izz="7.2e-05"/>
    </inertial>
    <visual>
      <origin rpy="0 0 0" xyz="0.020207 -0.000222 -0.17144"/>
      <geometry>
        <mesh filename="package://protoarm_description/meshes/humerus_1.stl" scale="0.001 0.001 0.001"/>
      </geometry>
      <material name="silver_default"/>
    </visual>
    <collision>
      <origin rpy="0 0 0" xyz="0.020207 -0.000222 -0.17144"/>
      <geometry>
        <mesh filename="package://protoarm_description/meshes/humerus_1.stl" scale="0.001 0.001 0.001"/>
      </geometry>
    </collision>
  </link>
  <link name="wrist_1">
    <inertial>
      <origin rpy="0 0 0" xyz="-0.017641925972066652 0.005015171425043511 0.005922235102376161"/>
      <mass value="0.1295112121194818"/>
      <inertia ixx="2e-05" ixy="4e-06" ixz="0.0" iyy="4e-05" iyz="-1e-06" izz="3.1e-05"/>
    </inertial>
    <visual>
      <origin rpy="0 0 0" xyz="0.107006 0.008795 -0.291635"/>
      <geometry>
        <mesh filename="package://protoarm_description/meshes/wrist_1.stl" scale="0.001 0.001 0.001"/>
      </geometry>
      <material name="silver_default"/>
    </visual>
    <collision>
      <origin rpy="0 0 0" xyz="0.107006 0.008795 -0.291635"/>
      <geometry>
        <mesh filename="package://protoarm_description/meshes/wrist_1.stl" scale="0.001 0.001 0.001"/>
      </geometry>
    </collision>
  </link>
  <link name="forearm_1">
    <inertial>
      <origin rpy="0 0 0" xyz="-0.039010552933404094 -0.008385818475854033 0.0024684495178514676"/>
      <mass value="0.39461490281663475"/>
      <inertia ixx="7.5e-05" ixy="-1.2e-05" ixz="2.2e-05" iyy="0.000456" iyz="1e-06" izz="0.000427"/>
    </inertial>
    <visual>
      <origin rpy="0 0 0" xyz="0.017319 -0.000979 -0.291403"/>
      <geometry>
        <mesh filename="package://protoarm_description/meshes/forearm_1.stl" scale="0.001 0.001 0.001"/>
      </geometry>
      <material name="silver_default"/>
    </visual>
    <collision>
      <origin rpy="0 0 0" xyz="0.017319 -0.000979 -0.291403"/>
      <geometry>
        <mesh filename="package://protoarm_description/meshes/forearm_1.stl" scale="0.001 0.001 0.001"/>
      </geometry>
    </collision>
  </link>
  <link name="palm_1">
    <inertial>
      <origin rpy="0 0 0" xyz="-0.023068563126707436 -0.0023275250054106368 0.007404383741293041"/>
      <mass value="0.12341304164534714"/>
      <inertia ixx="2.2e-05" ixy="-1.1e-05" ixz="1.4e-05" iyy="5.7e-05" iyz="4e-06" izz="6.2e-05"/>
    </inertial>
    <visual>
      <origin rpy="0 0 0" xyz="0.135027 -0.00469 -0.297799"/>
      <geometry>
        <mesh filename="package://protoarm_description/meshes/palm_1.stl" scale="0.001 0.001 0.001"/>
      </geometry>
      <material name="silver_default"/>
    </visual>
    <collision>
      <origin rpy="0 0 0" xyz="0.135027 -0.00469 -0.297799"/>
      <geometry>
        <mesh filename="package://protoarm_description/meshes/palm_1.stl" scale="0.001 0.001 0.001"/>
      </geometry>
    </collision>
  </link>
  <link name="right_gear_1">
    <inertial>
      <origin rpy="0 0 0" xyz="-0.0010058858944569649 0.005673483623448258 0.00585497431153309"/>
      <mass value="0.020736664284343446"/>
      <inertia ixx="3e-06" ixy="0.0" ixz="0.0" iyy="1e-06" iyz="0.0" izz="4e-06"/>
    </inertial>
    <visual>
      <origin rpy="0 0 0" xyz="0.172286 -0.013294 -0.313884"/>
      <geometry>
        <mesh filename="package://protoarm_description/meshes/right_gear_1.stl" scale="0.001 0.001 0.001"/>
      </geometry>
      <material name="silver_default"/>
    </visual>
    <collision>
      <origin rpy="0 0 0" xyz="0.172286 -0.013294 -0.313884"/>
      <geometry>
        <mesh filename="package://protoarm_description/meshes/right_gear_1.stl" scale="0.001 0.001 0.001"/>
      </geometry>
    </collision>
  </link>
  <link name="right_finger_1">
    <inertial>
      <origin rpy="0 0 0" xyz="-0.02680023622759173 -0.0061621588013440545 -0.002299785901809459"/>
      <mass value="0.04236978910676512"/>
      <inertia ixx="1e-06" ixy="-2e-06" ixz="1e-06" iyy="1.3e-05" iyz="0.0" izz="1.3e-05"/>
    </inertial>
    <visual>
      <origin rpy="0 0 0" xyz="0.176409 -0.043875 -0.316941"/>
      <geometry>
        <mesh filename="package://protoarm_description/meshes/right_finger_1.stl" scale="0.001 0.001 0.001"/>
      </geometry>
      <material name="silver_default"/>
    </visual>
    <collision>
      <origin rpy="0 0 0" xyz="0.176409 -0.043875 -0.316941"/>
      <geometry>
        <mesh filename="package://protoarm_description/meshes/right_finger_1.stl" scale="0.001 0.001 0.001"/>
      </geometry>
    </collision>
  </link>
  <link name="left_gear_1">
    <inertial>
      <origin rpy="0 0 0" xyz="0.0006784876279114505 -0.005448230083488522 0.006190904261327124"/>
      <mass value="0.020141998404349184"/>
      <inertia ixx="3e-06" ixy="0.0" ixz="0.0" iyy="1e-06" iyz="0.0" izz="3e-06"/>
    </inertial>
    <visual>
      <origin rpy="0 0 0" xyz="0.171552 0.013576 -0.314907"/>
      <geometry>
        <mesh filename="package://protoarm_description/meshes/left_gear_1.stl" scale="0.001 0.001 0.001"/>
      </geometry>
      <material name="silver_default"/>
    </visual>
    <collision>
      <origin rpy="0 0 0" xyz="0.171552 0.013576 -0.314907"/>
      <geometry>
        <mesh filename="package://protoarm_description/meshes/left_gear_1.stl" scale="0.001 0.001 0.001"/>
      </geometry>
    </collision>
  </link>
  <link name="left_finger_1">
    <inertial>
      <origin rpy="0 0 0" xyz="-0.026891203343919784 0.005545442542774857 -0.0027604616969521545"/>
      <mass value="0.04236978910676512"/>
      <inertia ixx="1e-06" ixy="2e-06" ixz="1e-06" iyy="1.3e-05" iyz="-0.0" izz="1.3e-05"/>
    </inertial>
    <visual>
      <origin rpy="0 0 0" xyz="0.16646 0.043771 -0.319796"/>
      <geometry>
        <mesh filename="package://protoarm_description/meshes/left_finger_1.stl" scale="0.001 0.001 0.001"/>
      </geometry>
      <material name="silver_default"/>
    </visual>
    <collision>
      <origin rpy="0 0 0" xyz="0.16646 0.043771 -0.319796"/>
      <geometry>
        <mesh filename="package://protoarm_description/meshes/left_finger_1.stl" scale="0.001 0.001 0.001"/>
      </geometry>
    </collision>
  </link>
  <joint name="grouding" type="fixed">
    <parent link="world"/>
    <child link="base_link"/>
  </joint>
  <joint name="Rev1" type="continuous">
    <origin rpy="0 0 0" xyz="-0.006279 0.004346 0.131179"/>
    <parent link="base_link"/>
    <child link="shoulder_1"/>
    <axis xyz="-0.002854 0.005633 0.99998"/>
  </joint>
  <joint name="Rev2" type="continuous">
    <origin rpy="0 0 0" xyz="-0.013928 -0.004124 0.040261"/>
    <parent link="shoulder_1"/>
    <child link="humerus_1"/>
    <axis xyz="-0.025335 0.999663 -0.005703"/>
  </joint>
  <joint name="Rev3" type="continuous">
    <origin rpy="0 0 0" xyz="-0.089687 -0.009774 0.000232"/>
    <parent link="forearm_1"/>
    <child link="wrist_1"/>
    <axis xyz="-0.997823 -0.02494 0.061059"/>
  </joint>
  <joint name="Rev4" type="continuous">
    <origin rpy="0 0 0" xyz="0.002888 0.000757 0.119963"/>
    <parent link="humerus_1"/>
    <child link="forearm_1"/>
    <axis xyz="0.025335 -0.999663 0.005703"/>
  </joint>
  <joint name="Rev5" type="continuous">
    <origin rpy="0 0 0" xyz="-0.028021 0.013485 0.006164"/>
    <parent link="wrist_1"/>
    <child link="palm_1"/>
    <axis xyz="0.027296 -0.998903 0.038055"/>
  </joint>
  <joint name="G_Rev2" type="continuous">
    <origin rpy="0 0 0" xyz="-0.037259 0.008604 0.016085"/>
    <parent link="palm_1"/>
    <child link="right_gear_1"/>
    <axis xyz="0.063894 0.039735 0.997165"/>
  </joint>
  <joint name="G_Rev3" type="continuous">
    <origin rpy="0 0 0" xyz="-0.004123 0.030581 0.003057"/>
    <parent link="right_gear_1"/>
    <child link="right_finger_1"/>
    <axis xyz="0.063894 0.039735 0.997165"/>
  </joint>
  <joint name="G_Rev1" type="continuous">
    <origin rpy="0 0 0" xyz="-0.036525 -0.018266 0.017108"/>
    <parent link="palm_1"/>
    <child link="left_gear_1"/>
    <axis xyz="0.063894 0.039735 0.997165"/>
  </joint>
  <joint name="G_Rev4" type="continuous">
    <origin rpy="0 0 0" xyz="0.005092 -0.030195 0.004889"/>
    <parent link="left_gear_1"/>
    <child link="left_finger_1"/>
    <axis xyz="0.063894 0.039735 0.997165"/>
  </joint>
</robot>
